Workbook

Sheet Method
A1: Method
A3: Goal
A4: Measure how structurally consistent the RDF graphs produced by five independent runs of the pipeline are for the same police report (atestado).
A5: Data
A6: 6 reports × 5 runs = 30 RDF/XML files. Run mapping per report: R1 = file without suffix, R2–R5 = files suffixed (1)–(4). The exact file names are listed in each report sheet.
A7: Shape of a triple
A8: Each triple (s, p, o) is mapped to a shape: the predicate is kept; each individual (instance IRI) is replaced by its named classes, e.g. <d:StolenGoods> (<SinTipo> if it has no type); vocabulary terms (classes, properties) are kept verbatim; literals become Lit^^datatype (the value is discarded); blank nodes are replaced by a canonical recursive signature of their structure, independent of the node ID.
A9: Triples whose subject is a blank node are folded into the signature of the node that references them, so they are not counted separately.
A10: c_X(f) = number of triples of graph X that map to shape f. Each graph therefore becomes a multiset of shapes.
A11: Metric: multiset (weighted) Jaccard, also known as Ruzicka similarity
A12: J_w(A,B) = Σ_f min(c_A(f), c_B(f)) / Σ_f max(c_A(f), c_B(f)) Range [0, 1]; 1 = identical shape multisets.
A13: Global value for n runs: J_w(X1..Xn) = Σ_f min_i c_i(f) / Σ_f max_i c_i(f) (here n = 5).
... A22: Because literal values are abstracted to their datatype, J_w measures structural agreement; it does not detect differences in values (amounts, dates…).

Sheet Summary
A1: Summary — run-to-run structural consistency of the RDF outputs (6 reports × 5 runs)
A2: All values are formulas that read the per-report sheets. Error bars in the first chart show the min–max range of the 10 pairwise values.
A4: Report | B4: Runs | C4: Mean J_w (full) | D4: SD (full) | E4: Min (full) | F4: Max (full) | G4: Global J_w 5 runs (full) | H4: Mean J_w (ABox) | I4: SD (ABox) | J4: Min (ABox) | K4: Max (ABox) | L4: Global J_w 5 runs (ABox) | M4: Distinct shapes/run (full) | N4: Distinct shapes/run (ABox) | O4: Triples/run (full) | P4: Triples/run (ABox) | Q4: err− full | R4: err+ full | S4: err− ABox | T4: err+ ABox
A5: Report 1 | B5: 5 | C5: =Report_1!P40 -> 0.93802899 | D5: =Report_1!P41 -> 0.048211265 | E5: =Report_1!P42 -> 0.88607595 | F5: =Report_1!P43 -> 1 | G5: =Report_1!P44 -> 0.88607595 | H5: =Report_1!Q40 -> 0.91495177 | I5: =Report_1!Q41 -> 0.065772593 | J5: =Report_1!Q42 -> 0.84482759 | K5: =Report_1!Q43 -> 1 | L5: =Report_1!Q44 -> 0.84482759 | M5: =Report_1!P45 -> 34.6 | N5: =Report_1!Q45 -> 13.6 | O5: =Report_1!P46 -> 74.2 | P5: =Report_1!Q46 -> 53.2 | Q5: =C5-E5 -> 0.051953036 | R5: =F5-C5 -> 0.061971015 | S5: =H5-J5 -> 0.070124186 | T5: =K5-H5 -> 0.085048228
A6: Report 2 | B6: 5 | C6: =Report_2!P40 -> 0.92941176 | D6: =Report_2!P41 -> 0.09112902 | E6: =Report_2!P42 -> 0.82352941 | F6: =Report_2!P43 -> 1 | G6: =Report_2!P44 -> 0.82352941 | H6: =Report_2!Q40 -> 0.85 | I6: =Report_2!Q41 -> 0.19364917 | J6: =Report_2!Q42 -> 0.625 | K6: =Report_2!Q43 -> 1 | L6: =Report_2!Q44 -> 0.625 | M6: =Report_2!P45 -> 28 | N6: =Report_2!Q45 -> 10 | O6: =Report_2!P46 -> 32.8 | P6: =Report_2!Q46 -> 14.8 | Q6: =C6-E6 -> 0.10588235 | R6: =F6-C6 -> 0.070588235 | S6: =H6-J6 -> 0.225 | T6: =K6-H6 -> 0.15
A7: Report 3 | B7: 5 | C7: =Report_3!P40 -> 1 | D7: =Report_3!P41 -> 0 | E7: =Report_3!P42 -> 1 | F7: =Report_3!P43 -> 1 | G7: =Report_3!P44 -> 1 | H7: =Report_3!Q40 -> 1 | I7: =Report_3!Q41 -> 0 | J7: =Report_3!Q42 -> 1 | K7: =Report_3!Q43 -> 1 | L7: =Report_3!Q44 -> 1 | M7: =Report_3!P45 -> 46 | N7: =Report_3!Q45 -> 19 | O7: =Report_3!P46 -> 50 | P7: =Report_3!Q46 -> 23 | Q7: =C7-E7 -> 0 | R7: =F7-C7 -> 0 | S7: =H7-J7 -> 0 | T7: =K7-H7 -> 0
A8: Report 4 | B8: 5 | C8: =Report_4!P40 -> 1 | D8: =Report_4!P41 -> 0 | E8: =Report_4!P42 -> 1 | F8: =Report_4!P43 -> 1 | G8: =Report_4!P44 -> 1 | H8: =Report_4!Q40 -> 1 | I8: =Report_4!Q41 -> 0 | J8: =Report_4!Q42 -> 1 | K8: =Report_4!Q43 -> 1 | L8: =Report_4!Q44 -> 1 | M8: =Report_4!P45 -> 31 | N8: =Report_4!Q45 -> 14 | O8: =Report_4!P46 -> 49 | P8: =Report_4!Q46 -> 32 | Q8: =C8-E8 -> 0 | R8: =F8-C8 -> 0 | S8: =H8-J8 -> 0 | T8: =K8-H8 -> 0
A9: Report 5 | B9: 5 | C9: =Report_5!P40 -> 1 | D9: =Report_5!P41 -> 0 | E9: =Report_5!P42 -> 1 | F9: =Report_5!P43 -> 1 | G9: =Report_5!P44 -> 1 | H9: =Report_5!Q40 -> 1 | I9: =Report_5!Q41 -> 0 | J9: =Report_5!Q42 -> 1 | K9: =Report_5!Q43 -> 1 | L9: =Report_5!Q44 -> 1 | M9: =Report_5!P45 -> 18 | N9: =Report_5!Q45 -> 8 | O9: =Report_5!P46 -> 22 | P9: =Report_5!Q46 -> 12 | Q9: =C9-E9 -> 0 | R9: =F9-C9 -> 0 | S9: =H9-J9 -> 0 | T9: =K9-H9 -> 0
A10: Report 6 | B10: 5 | C10: =Report_6!P40 -> 0.96521739 | D10: =Report_6!P41 -> 0.044904155 | E10: =Report_6!P42 -> 0.91304348 | F10: =Report_6!P43 -> 1 | G10: =Report_6!P44 -> 0.91304348 | H10: =Report_6!Q40 -> 0.93846154 | I10: =Report_6!Q41 -> 0.079445812 | J10: =Report_6!Q42 -> 0.84615385 | K10: =Report_6!Q43 -> 1 | L10: =Report_6!Q44 -> 0.84615385 | M10: =Report_6!P45 -> 36 | N10: =Report_6!Q45 -> 16 | O10: =Report_6!P46 -> 45.2 | P10: =Report_6!Q46 -> 25.2 | Q10: =C10-E10 -> 0.052173913 | R10: =F10-C10 -> 0.034782609 | S10: =H10-J10 -> 0.092307692 | T10: =K10-H10 -> 0.061538462
A11: All reports (60 pairs) | B11: =SUM(B5:B10) -> 30 | C11: =AVERAGE(Pairs!F5:F64) -> 0.97210969 | D11: =STDEV(Pairs!F5:F64) -> 0.053276391 | E11: =MIN(Pairs!F5:F64) -> 0.82352941 | F11: =MAX(Pairs!F5:F64) -> 1 | G11: =AVERAGE(G5:G10) -> 0.93710814 | H11: =AVERAGE(Pairs!G5:G64) -> 0.95056889 | I11: =STDEV(Pairs!G5:G64) -> 0.10266242 | J11: =MIN(Pairs!G5:G64) -> 0.625 | K11: =MAX(Pairs!G5:G64) -> 1 | L11: =AVERAGE(L5:L10) -> 0.88599691 | M11: =AVERAGE(M5:M10) -> 32.266667 | N11: =AVERAGE(N5:N10) -> 13.433333 | O11: =AVERAGE(O5:O10) -> 45.533333 | P11: =AVERAGE(P5:P10) -> 26.7
A12: Row 'All reports': mean/SD/min/max over the 60 pairwise values (Pairs sheet); 'Global' column = mean of the six per-report global values.
A14: Pairs with J_w = 1 (Full graph) | C14: =COUNTIF(Pairs!F5:F64,1) -> 45 | D14: of 60
A15: Pairs with J_w = 1 (ABox) | C15: =COUNTIF(Pairs!G5:G64,1) -> 45 | D15: of 60
A16: Reports with J_w = 1 in all 10 pairs (ABox) | C16: =COUNTIF(J5:J10,1) -> 3
A38: Lexical baseline — plain set Jaccard on exact triples (IRIs as written; triples with blank nodes excluded)
A39: Blue values are computed by jaccard_multiconjunto.py (function tripletas_exactas / individuos), not by Excel formulas: an exact-triple comparison cannot be expressed on the shape counts.
A40: Report | B40: Exact-triple Jaccard (mean of 10 pairs) | C40: Exact-triple Jaccard (min) | D40: Exact-triple Jaccard (max) | E40: Pairs with identical individual-IRI sets (of 10) | F40: Mean J_w (ABox) | G40: Gap: J_w (ABox) − exact
A41: Report 1 | B41: 0.89363 | C41: 0.777778 | D41: 1 | E41: 1 | F41: =H5 -> 0.91495177 | G41: =F41-B41 -> 0.021321772
A42: Report 2 | B42: 0.593846 | C42: 0.466667 | D42: 1 | E42: 1 | F42: =H6 -> 0.85 | G42: =F42-B42 -> 0.256154
A43: Report 3 | B43: 0.671622 | C43: 0.5625 | D43: 0.851852 | E43: 0 | F43: =H7 -> 1 | G43: =F43-B43 -> 0.328378
A44: Report 4 | B44: 0.487808 | C44: 0.306667 | D44: 0.921569 | E44: 0 | F44: =H8 -> 1 | G44: =F44-B44 -> 0.512192
A45: Report 5 | B45: 0.471448 | C45: 0.448276 | D45: 0.68 | E45: 0 | F45: =H9 -> 1 | G45: =F45-B45 -> 0.528552
A46: Report 6 | B46: 0.514597 | C46: 0.415385 | D46: 0.642857 | E46: 0 | F46: =H10 -> 0.93846154 | G46: =F46-B46 -> 0.42386454

Sheet Pairs
A1: All 60 pairwise values (10 pairs × 6 reports)
A2: Columns H–I only shift the x position so both scopes are visible side by side in the scatter chart.
A4: Report | B4: Report # | C4: Pair | D4: Run i | E4: Run j | F4: J_w full graph | G4: J_w ABox | H4: x (full, offset) | I4: x (ABox, offset)
A5: Report 1 | B5: 1 | C5: R1–R2 | D5: 1 | E5: 2 | F5: =Report_1!P28 -> 1 | G5: =Report_1!Q28 -> 1 | H5: =B5-0.15 -> 0.85 | I5: =B5+0.15 -> 1.15
A6: Report 1 | B6: 1 | C6: R1–R3 | D6: 1 | E6: 3 | F6: =Report_1!P29 -> 1 | G6: =Report_1!Q29 -> 1 | H6: =B6-0.15 -> 0.85 | I6: =B6+0.15 -> 1.15
A7: Report 1 | B7: 1 | C7: R1–R4 | D7: 1 | E7: 4 | F7: =Report_1!P30 -> 0.92105263 | G7: =Report_1!Q30 -> 0.89090909 | H7: =B7-0.15 -> 0.85 | I7: =B7+0.15 -> 1.15
A8: Report 1 | B8: 1 | C8: R1–R5 | D8: 1 | E8: 5 | F8: =Report_1!P31 -> 0.88607595 | G8: =Report_1!Q31 -> 0.84482759 | H8: =B8-0.15 -> 0.85 | I8: =B8+0.15 -> 1.15
A9: Report 1 | B9: 1 | C9: R2–R3 | D9: 2 | E9: 3 | F9: =Report_1!P32 -> 1 | G9: =Report_1!Q32 -> 1 | H9: =B9-0.15 -> 0.85 | I9: =B9+0.15 -> 1.15
A10: Report 1 | B10: 1 | C10: R2–R4 | D10: 2 | E10: 4 | F10: =Report_1!P33 -> 0.92105263 | G10: =Report_1!Q33 -> 0.89090909 | H10: =B10-0.15 -> 0.85 | I10: =B10+0.15 -> 1.15
A11: Report 1 | B11: 1 | C11: R2–R5 | D11: 2 | E11: 5 | F11: =Report_1!P34 -> 0.88607595 | G11: =Report_1!Q34 -> 0.84482759 | H11: =B11-0.15 -> 0.85 | I11: =B11+0.15 -> 1.15
A12: Report 1 | B12: 1 | C12: R3–R4 | D12: 3 | E12: 4 | F12: =Report_1!P35 -> 0.92105263 | G12: =Report_1!Q35 -> 0.89090909 | H12: =B12-0.15 -> 0.85 | I12: =B12+0.15 -> 1.15
A13: Report 1 | B13: 1 | C13: R3–R5 | D13: 3 | E13: 5 | F13: =Report_1!P36 -> 0.88607595 | G13: =Report_1!Q36 -> 0.84482759 | H13: =B13-0.15 -> 0.85 | I13: =B13+0.15 -> 1.15
A14: Report 1 | B14: 1 | C14: R4–R5 | D14: 4 | E14: 5 | F14: =Report_1!P37 -> 0.95890411 | G14: =Report_1!Q37 -> 0.94230769 | H14: =B14-0.15 -> 0.85 | I14: =B14+0.15 -> 1.15
A15: Report 2 | B15: 2 | C15: R1–R2 | D15: 1 | E15: 2 | F15: =Report_2!P28 -> 1 | G15: =Report_2!Q28 -> 1 | H15: =B15-0.15 -> 1.85 | I15: =B15+0.15 -> 2.15
A16: Report 2 | B16: 2 | C16: R1–R3 | D16: 1 | E16: 3 | F16: =Report_2!P29 -> 1 | G16: =Report_2!Q29 -> 1 | H16: =B16-0.15 -> 1.85 | I16: =B16+0.15 -> 2.15
A17: Report 2 | B17: 2 | C17: R1–R4 | D17: 1 | E17: 4 | F17: =Report_2!P30 -> 0.82352941 | G17: =Report_2!Q30 -> 0.625 | H17: =B17-0.15 -> 1.85 | I17: =B17+0.15 -> 2.15
A18: Report 2 | B18: 2 | C18: R1–R5 | D18: 1 | E18: 5 | F18: =Report_2!P31 -> 1 | G18: =Report_2!Q31 -> 1 | H18: =B18-0.15 -> 1.85 | I18: =B18+0.15 -> 2.15
A19: Report 2 | B19: 2 | C19: R2–R3 | D19: 2 | E19: 3 | F19: =Report_2!P32 -> 1 | G19: =Report_2!Q32 -> 1 | H19: =B19-0.15 -> 1.85 | I19: =B19+0.15 -> 2.15
A20: Report 2 | B20: 2 | C20: R2–R4 | D20: 2 | E20: 4 | F20: =Report_2!P33 -> 0.82352941 | G20: =Report_2!Q33 -> 0.625 | H20: =B20-0.15 -> 1.85 | I20: =B20+0.15 -> 2.15
A21: Report 2 | B21: 2 | C21: R2–R5 | D21: 2 | E21: 5 | F21: =Report_2!P34 -> 1 | G21: =Report_2!Q34 -> 1 | H21: =B21-0.15 -> 1.85 | I21: =B21+0.15 -> 2.15
A22: Report 2 | B22: 2 | C22: R3–R4 | D22: 3 | E22: 4 | F22: =Report_2!P35 -> 0.82352941 | G22: =Report_2!Q35 -> 0.625 | H22: =B22-0.15 -> 1.85 | I22: =B22+0.15 -> 2.15
A23: Report 2 | B23: 2 | C23: R3–R5 | D23: 3 | E23: 5 | F23: =Report_2!P36 -> 1 | G23: =Report_2!Q36 -> 1 | H23: =B23-0.15 -> 1.85 | I23: =B23+0.15 -> 2.15
A24: Report 2 | B24: 2 | C24: R4–R5 | D24: 4 | E24: 5 | F24: =Report_2!P37 -> 0.82352941 | G24: =Report_2!Q37 -> 0.625 | H24: =B24-0.15 -> 1.85 | I24: =B24+0.15 -> 2.15
A25: Report 3 | B25: 3 | C25: R1–R2 | D25: 1 | E25: 2 | F25: =Report_3!P28 -> 1 | G25: =Report_3!Q28 -> 1 | H25: =B25-0.15 -> 2.85 | I25: =B25+0.15 -> 3.15
A26: Report 3 | B26: 3 | C26: R1–R3 | D26: 1 | E26: 3 | F26: =Report_3!P29 -> 1 | G26: =Report_3!Q29 -> 1 | H26: =B26-0.15 -> 2.85 | I26: =B26+0.15 -> 3.15
A27: Report 3 | B27: 3 | C27: R1–R4 | D27: 1 | E27: 4 | F27: =Report_3!P30 -> 1 | G27: =Report_3!Q30 -> 1 | H27: =B27-0.15 -> 2.85 | I27: =B27+0.15 -> 3.15
A28: Report 3 | B28: 3 | C28: R1–R5 | D28: 1 | E28: 5 | F28: =Report_3!P31 -> 1 | G28: =Report_3!Q31 -> 1 | H28: =B28-0.15 -> 2.85 | I28: =B28+0.15 -> 3.15
A29: Report 3 | B29: 3 | C29: R2–R3 | D29: 2 | E29: 3 | F29: =Report_3!P32 -> 1 | G29: =Report_3!Q32 -> 1 | H29: =B29-0.15 -> 2.85 | I29: =B29+0.15 -> 3.15
A30: Report 3 | B30: 3 | C30: R2–R4 | D30: 2 | E30: 4 | F30: =Report_3!P33 -> 1 | G30: =Report_3!Q33 -> 1 | H30: =B30-0.15 -> 2.85 | I30: =B30+0.15 -> 3.15
A31: Report 3 | B31: 3 | C31: R2–R5 | D31: 2 | E31: 5 | F31: =Report_3!P34 -> 1 | G31: =Report_3!Q34 -> 1 | H31: =B31-0.15 -> 2.85 | I31: =B31+0.15 -> 3.15
A32: Report 3 | B32: 3 | C32: R3–R4 | D32: 3 | E32: 4 | F32: =Report_3!P35 -> 1 | G32: =Report_3!Q35 -> 1 | H32: =B32-0.15 -> 2.85 | I32: =B32+0.15 -> 3.15
A33: Report 3 | B33: 3 | C33: R3–R5 | D33: 3 | E33: 5 | F33: =Report_3!P36 -> 1 | G33: =Report_3!Q36 -> 1 | H33: =B33-0.15 -> 2.85 | I33: =B33+0.15 -> 3.15
A34: Report 3 | B34: 3 | C34: R4–R5 | D34: 4 | E34: 5 | F34: =Report_3!P37 -> 1 | G34: =Report_3!Q37 -> 1 | H34: =B34-0.15 -> 2.85 | I34: =B34+0.15 -> 3.15
A35: Report 4 | B35: 4 | C35: R1–R2 | D35: 1 | E35: 2 | F35: =Report_4!P28 -> 1 | G35: =Report_4!Q28 -> 1 | H35: =B35-0.15 -> 3.85 | I35: =B35+0.15 -> 4.15
A36: Report 4 | B36: 4 | C36: R1–R3 | D36: 1 | E36: 3 | F36: =Report_4!P29 -> 1 | G36: =Report_4!Q29 -> 1 | H36: =B36-0.15 -> 3.85 | I36: =B36+0.15 -> 4.15
A37: Report 4 | B37: 4 | C37: R1–R4 | D37: 1 | E37: 4 | F37: =Report_4!P30 -> 1 | G37: =Report_4!Q30 -> 1 | H37: =B37-0.15 -> 3.85 | I37: =B37+0.15 -> 4.15
A38: Report 4 | B38: 4 | C38: R1–R5 | D38: 1 | E38: 5 | F38: =Report_4!P31 -> 1 | G38: =Report_4!Q31 -> 1 | H38: =B38-0.15 -> 3.85 | I38: =B38+0.15 -> 4.15
A39: Report 4 | B39: 4 | C39: R2–R3 | D39: 2 | E39: 3 | F39: =Report_4!P32 -> 1 | G39: =Report_4!Q32 -> 1 | H39: =B39-0.15 -> 3.85 | I39: =B39+0.15 -> 4.15
A40: Report 4 | B40: 4 | C40: R2–R4 | D40: 2 | E40: 4 | F40: =Report_4!P33 -> 1 | G40: =Report_4!Q33 -> 1 | H40: =B40-0.15 -> 3.85 | I40: =B40+0.15 -> 4.15
A41: Report 4 | B41: 4 | C41: R2–R5 | D41: 2 | E41: 5 | F41: =Report_4!P34 -> 1 | G41: =Report_4!Q34 -> 1 | H41: =B41-0.15 -> 3.85 | I41: =B41+0.15 -> 4.15
...

Sheet Report_1
A1: Report 1 — shape counts per run and pairwise multiset Jaccard
A2: Blue cells = shape counts extracted from the RDF files (inputs). Black cells = formulas. Shaded rows = shapes whose count differs across runs.
A4: Shape ID | B4: Subject shape | C4: Predicate | D4: Object shape | E4: ABox (1) / TBox (0) | F4: R1 | G4: R2 | H4: R3 | I4: R4 | J4: R5 | K4: Min (5 runs) | L4: Max (5 runs) | M4: Max − Min | O4: Run | P4: Source RDF file
A5: F01 | B5: <d:Accused> | C5: rdf:type | D5: d:Accused | E5: 1 | F5: 1 | G5: 1 | H5: 1 | I5: 1 | J5: 1 | K5: =MIN(F5:J5) -> 1 | L5: =MAX(F5:J5) -> 1 | M5: =L5-K5 -> 0 | O5: R1 | P5: 1INFORME_Atestado1.rdf
A6: F02 | B6: <d:Punishment> | C6: rdf:type | D6: d:Punishment | E6: 1 | F6: 1 | G6: 1 | H6: 1 | I6: 1 | J6: 1 | K6: =MIN(F6:J6) -> 1 | L6: =MAX(F6:J6) -> 1 | M6: =L6-K6 -> 0 | O6: R2 | P6: 1INFORME_Atestado1 (1).rdf
A7: F03 | B7: <d:Report> | C7: rdf:type | D7: [owl:complementOf=[owl:onProperty=d:hasOffenceCharacteristic;owl:someValuesFrom=d:RobberyCharacteristic;rdf:type=owl:Restriction];rdf:type=owl:Class] | E7: 1 | F7: 1 | G7: 1 | H7: 1 | I7: 1 | J7: 1 | K7: =MIN(F7:J7) -> 1 | L7: =MAX(F7:J7) -> 1 | M7: =L7-K7 -> 0 | O7: R3 | P7: 1INFORME_Atestado1 (2).rdf
A8: F04 | B8: <d:Report> | C8: rdf:type | D8: d:Report | E8: 1 | F8: 1 | G8: 1 | H8: 1 | I8: 1 | J8: 1 | K8: =MIN(F8:J8) -> 1 | L8: =MAX(F8:J8) -> 1 | M8: =L8-K8 -> 0 | O8: R4 | P8: 1INFORME_Atestado1 (3).rdf
A9: F05 | B9: <d:StolenGoods> | C9: rdf:type | D9: d:StolenGoods | E9: 1 | F9: 8 | G9: 8 | H9: 8 | I9: 7 | J9: 7 | K9: =MIN(F9:J9) -> 7 | L9: =MAX(F9:J9) -> 8 | M9: =L9-K9 -> 1 | O9: R5 | P9: 1INFORME_Atestado1 (4).rdf
A10: F06 | B10: <d:Victim> | C10: rdf:type | D10: d:Victim | E10: 1 | F10: 1 | G10: 1 | H10: 1 | I10: 1 | J10: 1 | K10: =MIN(F10:J10) -> 1 | L10: =MAX(F10:J10) -> 1 | M10: =L10-K10 -> 0
A11: F07 | B11: <SinTipo> | C11: d:belongsTo | D11: <d:Victim> | E11: 1 | F11: 0 | G11: 0 | H11: 0 | I11: 0 | J11: 1 | K11: =MIN(F11:J11) -> 0 | L11: =MAX(F11:J11) -> 1 | M11: =L11-K11 -> 1 | O11: Pairwise J_w — full graph
A12: F08 | B12: <SinTipo> | C12: d:stolenBy | D12: <d:Accused> | E12: 1 | F12: 0 | G12: 0 | H12: 0 | I12: 0 | J12: 1 | K12: =MIN(F12:J12) -> 0 | L12: =MAX(F12:J12) -> 1 | M12: =L12-K12 -> 1 | P12: R1 | Q12: R2 | R12: R3 | S12: R4 | T12: R5
A13: F09 | B13: <SinTipo> | C13: d:usedByOwner | D13: <d:Victim> | E13: 1 | F13: 0 | G13: 0 | H13: 0 | I13: 0 | J13: 1 | K13: =MIN(F13:J13) -> 0 | L13: =MAX(F13:J13) -> 1 | M13: =L13-K13 -> 1 | O13: R1 | P13: =SUMPRODUCT((($F$5:$F$41<$F$5:$F$41)*$F$5:$F$41+($F$5:$F$41>=$F$5:$F$41)*$F$5:$F$41))/SUMPRODUCT((($F$5:$F$41>$F$5:$F$41)*$F$5:$F$41+($F$5:$F$41<=$F$5:$F$41)*$F$5:$F$41)) -> 1 | Q13: =SUMPRODUCT((($F$5:$F$41<$G$5:$G$41)*$F$5:$F$41+($F$5:$F$41>=$G$5:$G$41)*$G$5:$G$41))/SUMPRODUCT((($F$5:$F$41>$G$5:$G$41)*$F$5:$F$41+($F$5:$F$41<=$G$5:$G$41)*$G$5:$G$41)) -> 1 | R13: =SUMPRODUCT((($F$5:$F$41<$H$5:$H$41)*$F$5:$F$41+($F$5:$F$41>=$H$5:$H$41)*$H$5:$H$41))/SUMPRODUCT((($F$5:$F$41>$H$5:$H$41)*$F$5:$F$41+($F$5:$F$41<=$H$5:$H$41)*$H$5:$H$41)) -> 1 | S13: =SUMPRODUCT((($F$5:$F$41<$I$5:$I$41)*$F$5:$F$41+($F$5:$F$41>=$I$5:$I$41)*$I$5:$I$41))/SUMPRODUCT((($F$5:$F$41>$I$5:$I$41)*$F$5:$F$41+($F$5:$F$41<=$I$5:$I$41)*$I$5:$I$41)) -> 0.92105263 | T13: =SUMPRODUCT((($F$5:$F$41<$J$5:$J$41)*$F$5:$F$41+($F$5:$F$41>=$J$5:$J$41)*$J$5:$J$41))/SUMPRODUCT((($F$5:$F$41>$J$5:$J$41)*$F$5:$F$41+($F$5:$F$41<=$J$5:$J$41)*$J$5:$J$41)) -> 0.88607595
A14: F10 | B14: <d:Accused> | C14: d:hasPreviusSentence | D14: <d:Punishment> | E14: 1 | F14: 1 | G14: 1 | H14: 1 | I14: 1 | J14: 1 | K14: =MIN(F14:J14) -> 1 | L14: =MAX(F14:J14) -> 1 | M14: =L14-K14 -> 0 | O14: R2 | P14: =SUMPRODUCT((($G$5:$G$41<$F$5:$F$41)*$G$5:$G$41+($G$5:$G$41>=$F$5:$F$41)*$F$5:$F$41))/SUMPRODUCT((($G$5:$G$41>$F$5:$F$41)*$G$5:$G$41+($G$5:$G$41<=$F$5:$F$41)*$F$5:$F$41)) -> 1 | Q14: =SUMPRODUCT((($G$5:$G$41<$G$5:$G$41)*$G$5:$G$41+($G$5:$G$41>=$G$5:$G$41)*$G$5:$G$41))/SUMPRODUCT((($G$5:$G$41>$G$5:$G$41)*$G$5:$G$41+($G$5:$G$41<=$G$5:$G$41)*$G$5:$G$41)) -> 1 | R14: =SUMPRODUCT((($G$5:$G$41<$H$5:$H$41)*$G$5:$G$41+($G$5:$G$41>=$H$5:$H$41)*$H$5:$H$41))/SUMPRODUCT((($G$5:$G$41>$H$5:$H$41)*$G$5:$G$41+($G$5:$G$41<=$H$5:$H$41)*$H$5:$H$41)) -> 1 | S14: =SUMPRODUCT((($G$5:$G$41<$I$5:$I$41)*$G$5:$G$41+($G$5:$G$41>=$I$5:$I$41)*$I$5:$I$41))/SUMPRODUCT((($G$5:$G$41>$I$5:$I$41)*$G$5:$G$41+($G$5:$G$41<=$I$5:$I$41)*$I$5:$I$41)) -> 0.92105263 | T14: =SUMPRODUCT((($G$5:$G$41<$J$5:$J$41)*$G$5:$G$41+($G$5:$G$41>=$J$5:$J$41)*$J$5:$J$41))/SUMPRODUCT((($G$5:$G$41>$J$5:$J$41)*$G$5:$G$41+($G$5:$G$41<=$J$5:$J$41)*$J$5:$J$41)) -> 0.88607595
A15: F11 | B15: <d:Punishment> | C15: d:num | D15: Lit^^xsd:integer | E15: 1 | F15: 1 | G15: 1 | H15: 1 | I15: 1 | J15: 1 | K15: =MIN(F15:J15) -> 1 | L15: =MAX(F15:J15) -> 1 | M15: =L15-K15 -> 0 | O15: R3 | P15: =SUMPRODUCT((($H$5:$H$41<$F$5:$F$41)*$H$5:$H$41+($H$5:$H$41>=$F$5:$F$41)*$F$5:$F$41))/SUMPRODUCT((($H$5:$H$41>$F$5:$F$41)*$H$5:$H$41+($H$5:$H$41<=$F$5:$F$41)*$F$5:$F$41)) -> 1 | Q15: =SUMPRODUCT((($H$5:$H$41<$G$5:$G$41)*$H$5:$H$41+($H$5:$H$41>=$G$5:$G$41)*$G$5:$G$41))/SUMPRODUCT((($H$5:$H$41>$G$5:$G$41)*$H$5:$H$41+($H$5:$H$41<=$G$5:$G$41)*$G$5:$G$41)) -> 1 | R15: =SUMPRODUCT((($H$5:$H$41<$H$5:$H$41)*$H$5:$H$41+($H$5:$H$41>=$H$5:$H$41)*$H$5:$H$41))/SUMPRODUCT((($H$5:$H$41>$H$5:$H$41)*$H$5:$H$41+($H$5:$H$41<=$H$5:$H$41)*$H$5:$H$41)) -> 1 | S15: =SUMPRODUCT((($H$5:$H$41<$I$5:$I$41)*$H$5:$H$41+($H$5:$H$41>=$I$5:$I$41)*$I$5:$I$41))/SUMPRODUCT((($H$5:$H$41>$I$5:$I$41)*$H$5:$H$41+($H$5:$H$41<=$I$5:$I$41)*$I$5:$I$41)) -> 0.92105263 | T15: =SUMPRODUCT((($H$5:$H$41<$J$5:$J$41)*$H$5:$H$41+($H$5:$H$41>=$J$5:$J$41)*$J$5:$J$41))/SUMPRODUCT((($H$5:$H$41>$J$5:$J$41)*$H$5:$H$41+($H$5:$H$41<=$J$5:$J$41)*$J$5:$J$41)) -> 0.88607595
A16: F12 | B16: <d:Report> | C16: d:stolenthing | D16: <d:StolenGoods> | E16: 1 | F16: 8 | G16: 8 | H16: 8 | I16: 7 | J16: 7 | K16: =MIN(F16:J16) -> 7 | L16: =MAX(F16:J16) -> 8 | M16: =L16-K16 -> 1 | O16: R4 | P16: =SUMPRODUCT((($I$5:$I$41<$F$5:$F$41)*$I$5:$I$41+($I$5:$I$41>=$F$5:$F$41)*$F$5:$F$41))/SUMPRODUCT((($I$5:$I$41>$F$5:$F$41)*$I$5:$I$41+($I$5:$I$41<=$F$5:$F$41)*$F$5:$F$41)) -> 0.92105263 | Q16: =SUMPRODUCT((($I$5:$I$41<$G$5:$G$41)*$I$5:$I$41+($I$5:$I$41>=$G$5:$G$41)*$G$5:$G$41))/SUMPRODUCT((($I$5:$I$41>$G$5:$G$41)*$I$5:$I$41+($I$5:$I$41<=$G$5:$G$41)*$G$5:$G$41)) -> 0.92105263 | R16: =SUMPRODUCT((($I$5:$I$41<$H$5:$H$41)*$I$5:$I$41+($I$5:$I$41>=$H$5:$H$41)*$H$5:$H$41))/SUMPRODUCT((($I$5:$I$41>$H$5:$H$41)*$I$5:$I$41+($I$5:$I$41<=$H$5:$H$41)*$H$5:$H$41)) -> 0.92105263 | S16: =SUMPRODUCT((($I$5:$I$41<$I$5:$I$41)*$I$5:$I$41+($I$5:$I$41>=$I$5:$I$41)*$I$5:$I$41))/SUMPRODUCT((($I$5:$I$41>$I$5:$I$41)*$I$5:$I$41+($I$5:$I$41<=$I$5:$I$41)*$I$5:$I$41)) -> 1 | T16: =SUMPRODUCT((($I$5:$I$41<$J$5:$J$41)*$I$5:$I$41+($I$5:$I$41>=$J$5:$J$41)*$J$5:$J$41))/SUMPRODUCT((($I$5:$I$41>$J$5:$J$41)*$I$5:$I$41+($I$5:$I$41<=$J$5:$J$41)*$J$5:$J$41)) -> 0.95890411
A17: F13 | B17: <d:StolenGoods> | C17: d:ValueCost | D17: Lit^^xsd:decimal | E17: 1 | F17: 8 | G17: 8 | H17: 8 | I17: 7 | J17: 7 | K17: =MIN(F17:J17) -> 7 | L17: =MAX(F17:J17) -> 8 | M17: =L17-K17 -> 1 | O17: R5 | P17: =SUMPRODUCT((($J$5:$J$41<$F$5:$F$41)*$J$5:$J$41+($J$5:$J$41>=$F$5:$F$41)*$F$5:$F$41))/SUMPRODUCT((($J$5:$J$41>$F$5:$F$41)*$J$5:$J$41+($J$5:$J$41<=$F$5:$F$41)*$F$5:$F$41)) -> 0.88607595 | Q17: =SUMPRODUCT((($J$5:$J$41<$G$5:$G$41)*$J$5:$J$41+($J$5:$J$41>=$G$5:$G$41)*$G$5:$G$41))/SUMPRODUCT((($J$5:$J$41>$G$5:$G$41)*$J$5:$J$41+($J$5:$J$41<=$G$5:$G$41)*$G$5:$G$41)) -> 0.88607595 | R17: =SUMPRODUCT((($J$5:$J$41<$H$5:$H$41)*$J$5:$J$41+($J$5:$J$41>=$H$5:$H$41)*$H$5:$H$41))/SUMPRODUCT((($J$5:$J$41>$H$5:$H$41)*$J$5:$J$41+($J$5:$J$41<=$H$5:$H$41)*$H$5:$H$41)) -> 0.88607595 | S17: =SUMPRODUCT((($J$5:$J$41<$I$5:$I$41)*$J$5:$J$41+($J$5:$J$41>=$I$5:$I$41)*$I$5:$I$41))/SUMPRODUCT((($J$5:$J$41>$I$5:$I$41)*$J$5:$J$41+($J$5:$J$41<=$I$5:$I$41)*$I$5:$I$41)) -> 0.95890411 | T17: =SUMPRODUCT((($J$5:$J$41<$J$5:$J$41)*$J$5:$J$41+($J$5:$J$41>=$J$5:$J$41)*$J$5:$J$41))/SUMPRODUCT((($J$5:$J$41>$J$5:$J$41)*$J$5:$J$41+($J$5:$J$41<=$J$5:$J$41)*$J$5:$J$41)) -> 1
A18: F14 | B18: <d:StolenGoods> | C18: d:belongsTo | D18: <d:Victim> | E18: 1 | F18: 8 | G18: 8 | H18: 8 | I18: 7 | J18: 7 | K18: =MIN(F18:J18) -> 7 | L18: =MAX(F18:J18) -> 8 | M18: =L18-K18 -> 1
A19: F15 | B19: <d:StolenGoods> | C19: d:stolenBy | D19: <d:Accused> | E19: 1 | F19: 8 | G19: 8 | H19: 8 | I19: 7 | J19: 7 | K19: =MIN(F19:J19) -> 7 | L19: =MAX(F19:J19) -> 8 | M19: =L19-K19 -> 1 | O19: Pairwise J_w — ABox only
A20: F16 | B20: <d:StolenGoods> | C20: d:usedByOwner | D20: <d:Victim> | E20: 1 | F20: 8 | G20: 8 | H20: 8 | I20: 7 | J20: 7 | K20: =MIN(F20:J20) -> 7 | L20: =MAX(F20:J20) -> 8 | M20: =L20-K20 -> 1 | P20: R1 | Q20: R2 | R20: R3 | S20: R4 | T20: R5
A21: F17 | B21: d:Accused | C21: rdf:type | D21: owl:Class | E21: 0 | F21: 1 | G21: 1 | H21: 1 | I21: 1 | J21: 1 | K21: =MIN(F21:J21) -> 1 | L21: =MAX(F21:J21) -> 1 | M21: =L21-K21 -> 0 | O21: R1 | P21: =SUMPRODUCT($E$5:$E$41*(($F$5:$F$41<$F$5:$F$41)*$F$5:$F$41+($F$5:$F$41>=$F$5:$F$41)*$F$5:$F$41))/SUMPRODUCT($E$5:$E$41*(($F$5:$F$41>$F$5:$F$41)*$F$5:$F$41+($F$5:$F$41<=$F$5:$F$41)*$F$5:$F$41)) -> 1 | Q21: =SUMPRODUCT($E$5:$E$41*(($F$5:$F$41<$G$5:$G$41)*$F$5:$F$41+($F$5:$F$41>=$G$5:$G$41)*$G$5:$G$41))/SUMPRODUCT($E$5:$E$41*(($F$5:$F$41>$G$5:$G$41)*$F$5:$F$41+($F$5:$F$41<=$G$5:$G$41)*$G$5:$G$41)) -> 1 | R21: =SUMPRODUCT($E$5:$E$41*(($F$5:$F$41<$H$5:$H$41)*$F$5:$F$41+($F$5:$F$41>=$H$5:$H$41)*$H$5:$H$41))/SUMPRODUCT($E$5:$E$41*(($F$5:$F$41>$H$5:$H$41)*$F$5:$F$41+($F$5:$F$41<=$H$5:$H$41)*$H$5:$H$41)) -> 1 | S21: =SUMPRODUCT($E$5:$E$41*(($F$5:$F$41<$I$5:$I$41)*$F$5:$F$41+($F$5:$F$41>=$I$5:$I$41)*$I$5:$I$41))/SUMPRODUCT($E$5:$E$41*(($F$5:$F$41>$I$5:$I$41)*$F$5:$F$41+($F$5:$F$41<=$I$5:$I$41)*$I$5:$I$41)) -> 0.89090909 | T21: =SUMPRODUCT($E$5:$E$41*(($F$5:$F$41<$J$5:$J$41)*$F$5:$F$41+($F$5:$F$41>=$J$5:$J$41)*$J$5:$J$41))/SUMPRODUCT($E$5:$E$41*(($F$5:$F$41>$J$5:$J$41)*$F$5:$F$41+($F$5:$F$41<=$J$5:$J$41)*$J$5:$J$41)) -> 0.84482759
A22: F18 | B22: d:Punishment | C22: rdf:type | D22: owl:Class | E22: 0 | F22: 1 | G22: 1 | H22: 1 | I22: 1 | J22: 1 | K22: =MIN(F22:J22) -> 1 | L22: =MAX(F22:J22) -> 1 | M22: =L22-K22 -> 0 | O22: R2 | P22: =SUMPRODUCT($E$5:$E$41*(($G$5:$G$41<$F$5:$F$41)*$G$5:$G$41+($G$5:$G$41>=$F$5:$F$41)*$F$5:$F$41))/SUMPRODUCT($E$5:$E$41*(($G$5:$G$41>$F$5:$F$41)*$G$5:$G$41+($G$5:$G$41<=$F$5:$F$41)*$F$5:$F$41)) -> 1 | Q22: =SUMPRODUCT($E$5:$E$41*(($G$5:$G$41<$G$5:$G$41)*$G$5:$G$41+($G$5:$G$41>=$G$5:$G$41)*$G$5:$G$41))/SUMPRODUCT($E$5:$E$41*(($G$5:$G$41>$G$5:$G$41)*$G$5:$G$41+($G$5:$G$41<=$G$5:$G$41)*$G$5:$G$41)) -> 1 | R22: =SUMPRODUCT($E$5:$E$41*(($G$5:$G$41<$H$5:$H$41)*$G$5:$G$41+($G$5:$G$41>=$H$5:$H$41)*$H$5:$H$41))/SUMPRODUCT($E$5:$E$41*(($G$5:$G$41>$H$5:$H$41)*$G$5:$G$41+($G$5:$G$41<=$H$5:$H$41)*$H$5:$H$41)) -> 1 | S22: =SUMPRODUCT($E$5:$E$41*(($G$5:$G$41<$I$5:$I$41)*$G$5:$G$41+($G$5:$G$41>=$I$5:$I$41)*$I$5:$I$41))/SUMPRODUCT($E$5:$E$41*(($G$5:$G$41>$I$5:$I$41)*$G$5:$G$41+($G$5:$G$41<=$I$5:$I$41)*$I$5:$I$41)) -> 0.89090909 | T22: =SUMPRODUCT($E$5:$E$41*(($G$5:$G$41<$J$5:$J$41)*$G$5:$G$41+($G$5:$G$41>=$J$5:$J$41)*$J$5:$J$41))/SUMPRODUCT($E$5:$E$41*(($G$5:$G$41>$J$5:$J$41)*$G$5:$G$41+($G$5:$G$41<=$J$5:$J$41)*$J$5:$J$41)) -> 0.84482759
A23: F19 | B23: d:Report | C23: rdf:type | D23: owl:Class | E23: 0 | F23: 1 | G23: 1 | H23: 1 | I23: 1 | J23: 1 | K23: =MIN(F23:J23) -> 1 | L23: =MAX(F23:J23) -> 1 | M23: =L23-K23 -> 0 | O23: R3 | P23: =SUMPRODUCT($E$5:$E$41*(($H$5:$H$41<$F$5:$F$41)*$H$5:$H$41+($H$5:$H$41>=$F$5:$F$41)*$F$5:$F$41))/SUMPRODUCT($E$5:$E$41*(($H$5:$H$41>$F$5:$F$41)*$H$5:$H$41+($H$5:$H$41<=$F$5:$F$41)*$F$5:$F$41)) -> 1 | Q23: =SUMPRODUCT($E$5:$E$41*(($H$5:$H$41<$G$5:$G$41)*$H$5:$H$41+($H$5:$H$41>=$G$5:$G$41)*$G$5:$G$41))/SUMPRODUCT($E$5:$E$41*(($H$5:$H$41>$G$5:$G$41)*$H$5:$H$41+($H$5:$H$41<=$G$5:$G$41)*$G$5:$G$41)) -> 1 | R23: =SUMPRODUCT($E$5:$E$41*(($H$5:$H$41<$H$5:$H$41)*$H$5:$H$41+($H$5:$H$41>=$H$5:$H$41)*$H$5:$H$41))/SUMPRODUCT($E$5:$E$41*(($H$5:$H$41>$H$5:$H$41)*$H$5:$H$41+($H$5:$H$41<=$H$5:$H$41)*$H$5:$H$41)) -> 1 | S23: =SUMPRODUCT($E$5:$E$41*(($H$5:$H$41<$I$5:$I$41)*$H$5:$H$41+($H$5:$H$41>=$I$5:$I$41)*$I$5:$I$41))/SUMPRODUCT($E$5:$E$41*(($H$5:$H$41>$I$5:$I$41)*$H$5:$H$41+($H$5:$H$41<=$I$5:$I$41)*$I$5:$I$41)) -> 0.89090909 | T23: =SUMPRODUCT($E$5:$E$41*(($H$5:$H$41<$J$5:$J$41)*$H$5:$H$41+($H$5:$H$41>=$J$5:$J$41)*$J$5:$J$41))/SUMPRODUCT($E$5:$E$41*(($H$5:$H$41>$J$5:$J$41)*$H$5:$H$41+($H$5:$H$41<=$J$5:$J$41)*$J$5:$J$41)) -> 0.84482759
A24: F20 | B24: d:StolenGoods | C24: rdf:type | D24: owl:Class | E24: 0 | F24: 1 | G24: 1 | H24: 1 | I24: 1 | J24: 1 | K24: =MIN(F24:J24) -> 1 | L24: =MAX(F24:J24) -> 1 | M24: =L24-K24 -> 0 | O24: R4 | P24: =SUMPRODUCT($E$5:$E$41*(($I$5:$I$41<$F$5:$F$41)*$I$5:$I$41+($I$5:$I$41>=$F$5:$F$41)*$F$5:$F$41))/SUMPRODUCT($E$5:$E$41*(($I$5:$I$41>$F$5:$F$41)*$I$5:$I$41+($I$5:$I$41<=$F$5:$F$41)*$F$5:$F$41)) -> 0.89090909 | Q24: =SUMPRODUCT($E$5:$E$41*(($I$5:$I$41<$G$5:$G$41)*$I$5:$I$41+($I$5:$I$41>=$G$5:$G$41)*$G$5:$G$41))/SUMPRODUCT($E$5:$E$41*(($I$5:$I$41>$G$5:$G$41)*$I$5:$I$41+($I$5:$I$41<=$G$5:$G$41)*$G$5:$G$41)) -> 0.89090909 | R24: =SUMPRODUCT($E$5:$E$41*(($I$5:$I$41<$H$5:$H$41)*$I$5:$I$41+($I$5:$I$41>=$H$5:$H$41)*$H$5:$H$41))/SUMPRODUCT($E$5:$E$41*(($I$5:$I$41>$H$5:$H$41)*$I$5:$I$41+($I$5:$I$41<=$H$5:$H$41)*$H$5:$H$41)) -> 0.89090909 | S24: =SUMPRODUCT($E$5:$E$41*(($I$5:$I$41<$I$5:$I$41)*$I$5:$I$41+($I$5:$I$41>=$I$5:$I$41)*$I$5:$I$41))/SUMPRODUCT($E$5:$E$41*(($I$5:$I$41>$I$5:$I$41)*$I$5:$I$41+($I$5:$I$41<=$I$5:$I$41)*$I$5:$I$41)) -> 1 | T24: =SUMPRODUCT($E$5:$E$41*(($I$5:$I$41<$J$5:$J$41)*$I$5:$I$41+($I$5:$I$41>=$J$5:$J$41)*$J$5:$J$41))/SUMPRODUCT($E$5:$E$41*(($I$5:$I$41>$J$5:$J$41)*$I$5:$I$41+($I$5:$I$41<=$J$5:$J$41)*$J$5:$J$41)) -> 0.94230769
A25: F21 | B25: d:Victim | C25: rdf:type | D25: owl:Class | E25: 0 | F25: 1 | G25: 1 | H25: 1 | I25: 1 | J25: 1 | K25: =MIN(F25:J25) -> 1 | L25: =MAX(F25:J25) -> 1 | M25: =L25-K25 -> 0 | O25: R5 | P25: =SUMPRODUCT($E$5:$E$41*(($J$5:$J$41<$F$5:$F$41)*$J$5:$J$41+($J$5:$J$41>=$F$5:$F$41)*$F$5:$F$41))/SUMPRODUCT($E$5:$E$41*(($J$5:$J$41>$F$5:$F$41)*$J$5:$J$41+($J$5:$J$41<=$F$5:$F$41)*$F$5:$F$41)) -> 0.84482759 | Q25: =SUMPRODUCT($E$5:$E$41*(($J$5:$J$41<$G$5:$G$41)*$J$5:$J$41+($J$5:$J$41>=$G$5:$G$41)*$G$5:$G$41))/SUMPRODUCT($E$5:$E$41*(($J$5:$J$41>$G$5:$G$41)*$J$5:$J$41+($J$5:$J$41<=$G$5:$G$41)*$G$5:$G$41)) -> 0.84482759 | R25: =SUMPRODUCT($E$5:$E$41*(($J$5:$J$41<$H$5:$H$41)*$J$5:$J$41+($J$5:$J$41>=$H$5:$H$41)*$H$5:$H$41))/SUMPRODUCT($E$5:$E$41*(($J$5:$J$41>$H$5:$H$41)*$J$5:$J$41+($J$5:$J$41<=$H$5:$H$41)*$H$5:$H$41)) -> 0.84482759 | S25: =SUMPRODUCT($E$5:$E$41*(($J$5:$J$41<$I$5:$I$41)*$J$5:$J$41+($J$5:$J$41>=$I$5:$I$41)*$I$5:$I$41))/SUMPRODUCT($E$5:$E$41*(($J$5:$J$41>$I$5:$I$41)*$J$5:$J$41+($J$5:$J$41<=$I$5:$I$41)*$I$5:$I$41)) -> 0.94230769 | T25: =SUMPRODUCT($E$5:$E$41*(($J$5:$J$41<$J$5:$J$41)*$J$5:$J$41+($J$5:$J$41>=$J$5:$J$41)*$J$5:$J$41))/SUMPRODUCT($E$5:$E$41*(($J$5:$J$41>$J$5:$J$41)*$J$5:$J$41+($J$5:$J$41<=$J$5:$J$41)*$J$5:$J$41)) -> 1
A26: F22 | B26: d:belongsTo | C26: rdf:type | D26: owl:ObjectProperty | E26: 0 | F26: 1 | G26: 1 | H26: 1 | I26: 1 | J26: 1 | K26: =MIN(F26:J26) -> 1 | L26: =MAX(F26:J26) -> 1 | M26: =L26-K26 -> 0
A27: F23 | B27: d:hasPreviusSentence | C27: rdf:type | D27: owl:ObjectProperty | E27: 0 | F27: 1 | G27: 1 | H27: 1 | I27: 1 | J27: 1 | K27: =MIN(F27:J27) -> 1 | L27: =MAX(F27:J27) -> 1 | M27: =L27-K27 -> 0 | O27: Pair | P27: J_w full graph | Q27: J_w ABox
A28: F24 | B28: d:nombre | C28: rdf:type | D28: owl:DatatypeProperty | E28: 0 | F28: 1 | G28: 1 | H28: 1 | I28: 1 | J28: 1 | K28: =MIN(F28:J28) -> 1 | L28: =MAX(F28:J28) -> 1 | M28: =L28-K28 -> 0 | O28: R1–R2 | P28: =Q13 -> 1 | Q28: =Q21 -> 1
A29: F25 | B29: d:rango | C29: rdf:type | D29: owl:DatatypeProperty | E29: 0 | F29: 1 | G29: 1 | H29: 1 | I29: 1 | J29: 1 | K29: =MIN(F29:J29) -> 1 | L29: =MAX(F29:J29) -> 1 | M29: =L29-K29 -> 0 | O29: R1–R3 | P29: =R13 -> 1 | Q29: =R21 -> 1
A30: F26 | B30: d:stolenBy | C30: rdf:type | D30: owl:ObjectProperty | E30: 0 | F30: 1 | G30: 1 | H30: 1 | I30: 1 | J30: 1 | K30: =MIN(F30:J30) -> 1 | L30: =MAX(F30:J30) -> 1 | M30: =L30-K30 -> 0 | O30: R1–R4 | P30: =S13 -> 0.92105263 | Q30: =S21 -> 0.89090909
A31: F27 | B31: d:stolenthing | C31: rdf:type | D31: owl:ObjectProperty | E31: 0 | F31: 1 | G31: 1 | H31: 1 | I31: 1 | J31: 1 | K31: =MIN(F31:J31) -> 1 | L31: =MAX(F31:J31) -> 1 | M31: =L31-K31 -> 0 | O31: R1–R5 | P31: =T13 -> 0.88607595 | Q31: =T21 -> 0.84482759
A32: F28 | B32: d:usedByOwner | C32: rdf:type | D32: owl:ObjectProperty | E32: 0 | F32: 1 | G32: 1 | H32: 1 | I32: 1 | J32: 1 | K32: =MIN(F32:J32) -> 1 | L32: =MAX(F32:J32) -> 1 | M32: =L32-K32 -> 0 | O32: R2–R3 | P32: =R14 -> 1 | Q32: =R22 -> 1
A33: F29 | B33: d:valor | C33: rdf:type | D33: owl:DatatypeProperty | E33: 0 | F33: 1 | G33: 1 | H33: 1 | I33: 1 | J33: 1 | K33: =MIN(F33:J33) -> 1 | L33: =MAX(F33:J33) -> 1 | M33: =L33-K33 -> 0 | O33: R2–R4 | P33: =S14 -> 0.92105263 | Q33: =S22 -> 0.89090909
A34: F30 | B34: d:belongsTo | C34: rdfs:label | D34: Lit | E34: 0 | F34: 1 | G34: 1 | H34: 1 | I34: 1 | J34: 1 | K34: =MIN(F34:J34) -> 1 | L34: =MAX(F34:J34) -> 1 | M34: =L34-K34 -> 0 | O34: R2–R5 | P34: =T14 -> 0.88607595 | Q34: =T22 -> 0.84482759
A35: F31 | B35: d:hasPreviusSentence | C35: rdfs:label | D35: Lit | E35: 0 | F35: 1 | G35: 1 | H35: 1 | I35: 1 | J35: 1 | K35: =MIN(F35:J35) -> 1 | L35: =MAX(F35:J35) -> 1 | M35: =L35-K35 -> 0 | O35: R3–R4 | P35: =S15 -> 0.92105263 | Q35: =S23 -> 0.89090909
A36: F32 | B36: d:nombre | C36: rdfs:label | D36: Lit | E36: 0 | F36: 1 | G36: 1 | H36: 1 | I36: 1 | J36: 1 | K36: =MIN(F36:J36) -> 1 | L36: =MAX(F36:J36) -> 1 | M36: =L36-K36 -> 0 | O36: R3–R5 | P36: =T15 -> 0.88607595 | Q36: =T23 -> 0.84482759
A37: F33 | B37: d:rango | C37: rdfs:label | D37: Lit | E37: 0 | F37: 1 | G37: 1 | H37: 1 | I37: 1 | J37: 1 | K37: =MIN(F37:J37) -> 1 | L37: =MAX(F37:J37) -> 1 | M37: =L37-K37 -> 0 | O37: R4–R5 | P37: =T16 -> 0.95890411 | Q37: =T24 -> 0.94230769
A38: F34 | B38: d:stolenBy | C38: rdfs:label | D38: Lit | E38: 0 | F38: 1 | G38: 1 | H38: 1 | I38: 1 | J38: 1 | K38: =MIN(F38:J38) -> 1 | L38: =MAX(F38:J38) -> 1 | M38: =L38-K38 -> 0
A39: F35 | B39: d:stolenthing | C39: rdfs:label | D39: Lit | E39: 0 | F39: 1 | G39: 1 | H39: 1 | I39: 1 | J39: 1 | K39: =MIN(F39:J39) -> 1 | L39: =MAX(F39:J39) -> 1 | M39: =L39-K39 -> 0 | O39: Statistic | P39: Full graph | Q39: ABox
A40: F36 | B40: d:usedByOwner | C40: rdfs:label | D40: Lit | E40: 0 | F40: 1 | G40: 1 | H40: 1 | I40: 1 | J40: 1 | K40: =MIN(F40:J40) -> 1 | L40: =MAX(F40:J40) -> 1 | M40: =L40-K40 -> 0 | O40: Mean of the 10 pairs | P40: =AVERAGE(P28:P37) -> 0.93802899 | Q40: =AVERAGE(Q28:Q37) -> 0.91495177
A41: F37 | B41: d:valor | C41: rdfs:label | D41: Lit | E41: 0 | F41: 1 | G41: 1 | H41: 1 | I41: 1 | J41: 1 | K41: =MIN(F41:J41) -> 1 | L41: =MAX(F41:J41) -> 1 | M41: =L41-K41 -> 0 | O41: SD of the 10 pairs (sample) | P41: =STDEV(P28:P37) -> 0.048211265 | Q41: =STDEV(Q28:Q37) -> 0.065772593
...

Sheet Report_2
A1: Report 2 — shape counts per run and pairwise multiset Jaccard
A2: Blue cells = shape counts extracted from the RDF files (inputs). Black cells = formulas. Shaded rows = shapes whose count differs across runs.
A4: Shape ID | B4: Subject shape | C4: Predicate | D4: Object shape | E4: ABox (1) / TBox (0) | F4: R1 | G4: R2 | H4: R3 | I4: R4 | J4: R5 | K4: Min (5 runs) | L4: Max (5 runs) | M4: Max − Min | O4: Run | P4: Source RDF file
A5: F01 | B5: <d:Accused> | C5: rdf:type | D5: d:Accused | E5: 1 | F5: 1 | G5: 1 | H5: 1 | I5: 1 | J5: 1 | K5: =MIN(F5:J5) -> 1 | L5: =MAX(F5:J5) -> 1 | M5: =L5-K5 -> 0 | O5: R1 | P5: 1INFORME_Atestado2.rdf
A6: F02 | B6: <d:Report> | C6: rdf:type | D6: [owl:complementOf=[owl:onProperty=d:hasOffenceCharacteristic;owl:someValuesFrom=d:RobberyCharacteristic;rdf:type=owl:Restriction];rdf:type=owl:Class] | E6: 1 | F6: 1 | G6: 1 | H6: 1 | I6: 1 | J6: 1 | K6: =MIN(F6:J6) -> 1 | L6: =MAX(F6:J6) -> 1 | M6: =L6-K6 -> 0 | O6: R2 | P6: 1INFORME_Atestado2 (1).rdf
A7: F03 | B7: <d:Report> | C7: rdf:type | D7: d:Report | E7: 1 | F7: 1 | G7: 1 | H7: 1 | I7: 1 | J7: 1 | K7: =MIN(F7:J7) -> 1 | L7: =MAX(F7:J7) -> 1 | M7: =L7-K7 -> 0 | O7: R3 | P7: 1INFORME_Atestado2 (2).rdf
A8: F04 | B8: <d:StolenGoods> | C8: rdf:type | D8: d:StolenGoods | E8: 1 | F8: 2 | G8: 2 | H8: 2 | I8: 1 | J8: 2 | K8: =MIN(F8:J8) -> 1 | L8: =MAX(F8:J8) -> 2 | M8: =L8-K8 -> 1 | O8: R4 | P8: 1INFORME_Atestado2 (3).rdf
A9: F05 | B9: <d:Victim> | C9: rdf:type | D9: d:Victim | E9: 1 | F9: 1 | G9: 1 | H9: 1 | I9: 1 | J9: 1 | K9: =MIN(F9:J9) -> 1 | L9: =MAX(F9:J9) -> 1 | M9: =L9-K9 -> 0 | O9: R5 | P9: 1INFORME_Atestado2 (4).rdf
A10: F06 | B10: <d:Report> | C10: d:stolenthing | D10: <d:StolenGoods> | E10: 1 | F10: 2 | G10: 2 | H10: 2 | I10: 1 | J10: 2 | K10: =MIN(F10:J10) -> 1 | L10: =MAX(F10:J10) -> 2 | M10: =L10-K10 -> 1
A11: F07 | B11: <d:StolenGoods> | C11: d:ValueCost | D11: Lit^^xsd:decimal | E11: 1 | F11: 2 | G11: 2 | H11: 2 | I11: 1 | J11: 2 | K11: =MIN(F11:J11) -> 1 | L11: =MAX(F11:J11) -> 2 | M11: =L11-K11 -> 1 | O11: Pairwise J_w — full graph
A12: F08 | B12: <d:StolenGoods> | C12: d:belongsTo | D12: <d:Victim> | E12: 1 | F12: 2 | G12: 2 | H12: 2 | I12: 1 | J12: 2 | K12: =MIN(F12:J12) -> 1 | L12: =MAX(F12:J12) -> 2 | M12: =L12-K12 -> 1 | P12: R1 | Q12: R2 | R12: R3 | S12: R4 | T12: R5
A13: F09 | B13: <d:StolenGoods> | C13: d:stolenBy | D13: <d:Accused> | E13: 1 | F13: 2 | G13: 2 | H13: 2 | I13: 1 | J13: 2 | K13: =MIN(F13:J13) -> 1 | L13: =MAX(F13:J13) -> 2 | M13: =L13-K13 -> 1 | O13: R1 | P13: =SUMPRODUCT((($F$5:$F$32<$F$5:$F$32)*$F$5:$F$32+($F$5:$F$32>=$F$5:$F$32)*$F$5:$F$32))/SUMPRODUCT((($F$5:$F$32>$F$5:$F$32)*$F$5:$F$32+($F$5:$F$32<=$F$5:$F$32)*$F$5:$F$32)) -> 1 | Q13: =SUMPRODUCT((($F$5:$F$32<$G$5:$G$32)*$F$5:$F$32+($F$5:$F$32>=$G$5:$G$32)*$G$5:$G$32))/SUMPRODUCT((($F$5:$F$32>$G$5:$G$32)*$F$5:$F$32+($F$5:$F$32<=$G$5:$G$32)*$G$5:$G$32)) -> 1 | R13: =SUMPRODUCT((($F$5:$F$32<$H$5:$H$32)*$F$5:$F$32+($F$5:$F$32>=$H$5:$H$32)*$H$5:$H$32))/SUMPRODUCT((($F$5:$F$32>$H$5:$H$32)*$F$5:$F$32+($F$5:$F$32<=$H$5:$H$32)*$H$5:$H$32)) -> 1 | S13: =SUMPRODUCT((($F$5:$F$32<$I$5:$I$32)*$F$5:$F$32+($F$5:$F$32>=$I$5:$I$32)*$I$5:$I$32))/SUMPRODUCT((($F$5:$F$32>$I$5:$I$32)*$F$5:$F$32+($F$5:$F$32<=$I$5:$I$32)*$I$5:$I$32)) -> 0.82352941 | T13: =SUMPRODUCT((($F$5:$F$32<$J$5:$J$32)*$F$5:$F$32+($F$5:$F$32>=$J$5:$J$32)*$J$5:$J$32))/SUMPRODUCT((($F$5:$F$32>$J$5:$J$32)*$F$5:$F$32+($F$5:$F$32<=$J$5:$J$32)*$J$5:$J$32)) -> 1
A14: F10 | B14: <d:StolenGoods> | C14: d:usedByOwner | D14: <d:Victim> | E14: 1 | F14: 2 | G14: 2 | H14: 2 | I14: 1 | J14: 2 | K14: =MIN(F14:J14) -> 1 | L14: =MAX(F14:J14) -> 2 | M14: =L14-K14 -> 1 | O14: R2 | P14: =SUMPRODUCT((($G$5:$G$32<$F$5:$F$32)*$G$5:$G$32+($G$5:$G$32>=$F$5:$F$32)*$F$5:$F$32))/SUMPRODUCT((($G$5:$G$32>$F$5:$F$32)*$G$5:$G$32+($G$5:$G$32<=$F$5:$F$32)*$F$5:$F$32)) -> 1 | Q14: =SUMPRODUCT((($G$5:$G$32<$G$5:$G$32)*$G$5:$G$32+($G$5:$G$32>=$G$5:$G$32)*$G$5:$G$32))/SUMPRODUCT((($G$5:$G$32>$G$5:$G$32)*$G$5:$G$32+($G$5:$G$32<=$G$5:$G$32)*$G$5:$G$32)) -> 1 | R14: =SUMPRODUCT((($G$5:$G$32<$H$5:$H$32)*$G$5:$G$32+($G$5:$G$32>=$H$5:$H$32)*$H$5:$H$32))/SUMPRODUCT((($G$5:$G$32>$H$5:$H$32)*$G$5:$G$32+($G$5:$G$32<=$H$5:$H$32)*$H$5:$H$32)) -> 1 | S14: =SUMPRODUCT((($G$5:$G$32<$I$5:$I$32)*$G$5:$G$32+($G$5:$G$32>=$I$5:$I$32)*$I$5:$I$32))/SUMPRODUCT((($G$5:$G$32>$I$5:$I$32)*$G$5:$G$32+($G$5:$G$32<=$I$5:$I$32)*$I$5:$I$32)) -> 0.82352941 | T14: =SUMPRODUCT((($G$5:$G$32<$J$5:$J$32)*$G$5:$G$32+($G$5:$G$32>=$J$5:$J$32)*$J$5:$J$32))/SUMPRODUCT((($G$5:$G$32>$J$5:$J$32)*$G$5:$G$32+($G$5:$G$32<=$J$5:$J$32)*$J$5:$J$32)) -> 1
A15: F11 | B15: d:Accused | C15: rdf:type | D15: owl:Class | E15: 0 | F15: 1 | G15: 1 | H15: 1 | I15: 1 | J15: 1 | K15: =MIN(F15:J15) -> 1 | L15: =MAX(F15:J15) -> 1 | M15: =L15-K15 -> 0 | O15: R3 | P15: =SUMPRODUCT((($H$5:$H$32<$F$5:$F$32)*$H$5:$H$32+($H$5:$H$32>=$F$5:$F$32)*$F$5:$F$32))/SUMPRODUCT((($H$5:$H$32>$F$5:$F$32)*$H$5:$H$32+($H$5:$H$32<=$F$5:$F$32)*$F$5:$F$32)) -> 1 | Q15: =SUMPRODUCT((($H$5:$H$32<$G$5:$G$32)*$H$5:$H$32+($H$5:$H$32>=$G$5:$G$32)*$G$5:$G$32))/SUMPRODUCT((($H$5:$H$32>$G$5:$G$32)*$H$5:$H$32+($H$5:$H$32<=$G$5:$G$32)*$G$5:$G$32)) -> 1 | R15: =SUMPRODUCT((($H$5:$H$32<$H$5:$H$32)*$H$5:$H$32+($H$5:$H$32>=$H$5:$H$32)*$H$5:$H$32))/SUMPRODUCT((($H$5:$H$32>$H$5:$H$32)*$H$5:$H$32+($H$5:$H$32<=$H$5:$H$32)*$H$5:$H$32)) -> 1 | S15: =SUMPRODUCT((($H$5:$H$32<$I$5:$I$32)*$H$5:$H$32+($H$5:$H$32>=$I$5:$I$32)*$I$5:$I$32))/SUMPRODUCT((($H$5:$H$32>$I$5:$I$32)*$H$5:$H$32+($H$5:$H$32<=$I$5:$I$32)*$I$5:$I$32)) -> 0.82352941 | T15: =SUMPRODUCT((($H$5:$H$32<$J$5:$J$32)*$H$5:$H$32+($H$5:$H$32>=$J$5:$J$32)*$J$5:$J$32))/SUMPRODUCT((($H$5:$H$32>$J$5:$J$32)*$H$5:$H$32+($H$5:$H$32<=$J$5:$J$32)*$J$5:$J$32)) -> 1
A16: F12 | B16: d:Report | C16: rdf:type | D16: owl:Class | E16: 0 | F16: 1 | G16: 1 | H16: 1 | I16: 1 | J16: 1 | K16: =MIN(F16:J16) -> 1 | L16: =MAX(F16:J16) -> 1 | M16: =L16-K16 -> 0 | O16: R4 | P16: =SUMPRODUCT((($I$5:$I$32<$F$5:$F$32)*$I$5:$I$32+($I$5:$I$32>=$F$5:$F$32)*$F$5:$F$32))/SUMPRODUCT((($I$5:$I$32>$F$5:$F$32)*$I$5:$I$32+($I$5:$I$32<=$F$5:$F$32)*$F$5:$F$32)) -> 0.82352941 | Q16: =SUMPRODUCT((($I$5:$I$32<$G$5:$G$32)*$I$5:$I$32+($I$5:$I$32>=$G$5:$G$32)*$G$5:$G$32))/SUMPRODUCT((($I$5:$I$32>$G$5:$G$32)*$I$5:$I$32+($I$5:$I$32<=$G$5:$G$32)*$G$5:$G$32)) -> 0.82352941 | R16: =SUMPRODUCT((($I$5:$I$32<$H$5:$H$32)*$I$5:$I$32+($I$5:$I$32>=$H$5:$H$32)*$H$5:$H$32))/SUMPRODUCT((($I$5:$I$32>$H$5:$H$32)*$I$5:$I$32+($I$5:$I$32<=$H$5:$H$32)*$H$5:$H$32)) -> 0.82352941 | S16: =SUMPRODUCT((($I$5:$I$32<$I$5:$I$32)*$I$5:$I$32+($I$5:$I$32>=$I$5:$I$32)*$I$5:$I$32))/SUMPRODUCT((($I$5:$I$32>$I$5:$I$32)*$I$5:$I$32+($I$5:$I$32<=$I$5:$I$32)*$I$5:$I$32)) -> 1 | T16: =SUMPRODUCT((($I$5:$I$32<$J$5:$J$32)*$I$5:$I$32+($I$5:$I$32>=$J$5:$J$32)*$J$5:$J$32))/SUMPRODUCT((($I$5:$I$32>$J$5:$J$32)*$I$5:$I$32+($I$5:$I$32<=$J$5:$J$32)*$J$5:$J$32)) -> 0.82352941
A17: F13 | B17: d:StolenGoods | C17: rdf:type | D17: owl:Class | E17: 0 | F17: 1 | G17: 1 | H17: 1 | I17: 1 | J17: 1 | K17: =MIN(F17:J17) -> 1 | L17: =MAX(F17:J17) -> 1 | M17: =L17-K17 -> 0 | O17: R5 | P17: =SUMPRODUCT((($J$5:$J$32<$F$5:$F$32)*$J$5:$J$32+($J$5:$J$32>=$F$5:$F$32)*$F$5:$F$32))/SUMPRODUCT((($J$5:$J$32>$F$5:$F$32)*$J$5:$J$32+($J$5:$J$32<=$F$5:$F$32)*$F$5:$F$32)) -> 1 | Q17: =SUMPRODUCT((($J$5:$J$32<$G$5:$G$32)*$J$5:$J$32+($J$5:$J$32>=$G$5:$G$32)*$G$5:$G$32))/SUMPRODUCT((($J$5:$J$32>$G$5:$G$32)*$J$5:$J$32+($J$5:$J$32<=$G$5:$G$32)*$G$5:$G$32)) -> 1 | R17: =SUMPRODUCT((($J$5:$J$32<$H$5:$H$32)*$J$5:$J$32+($J$5:$J$32>=$H$5:$H$32)*$H$5:$H$32))/SUMPRODUCT((($J$5:$J$32>$H$5:$H$32)*$J$5:$J$32+($J$5:$J$32<=$H$5:$H$32)*$H$5:$H$32)) -> 1 | S17: =SUMPRODUCT((($J$5:$J$32<$I$5:$I$32)*$J$5:$J$32+($J$5:$J$32>=$I$5:$I$32)*$I$5:$I$32))/SUMPRODUCT((($J$5:$J$32>$I$5:$I$32)*$J$5:$J$32+($J$5:$J$32<=$I$5:$I$32)*$I$5:$I$32)) -> 0.82352941 | T17: =SUMPRODUCT((($J$5:$J$32<$J$5:$J$32)*$J$5:$J$32+($J$5:$J$32>=$J$5:$J$32)*$J$5:$J$32))/SUMPRODUCT((($J$5:$J$32>$J$5:$J$32)*$J$5:$J$32+($J$5:$J$32<=$J$5:$J$32)*$J$5:$J$32)) -> 1
A18: F14 | B18: d:Victim | C18: rdf:type | D18: owl:Class | E18: 0 | F18: 1 | G18: 1 | H18: 1 | I18: 1 | J18: 1 | K18: =MIN(F18:J18) -> 1 | L18: =MAX(F18:J18) -> 1 | M18: =L18-K18 -> 0
A19: F15 | B19: d:belongsTo | C19: rdf:type | D19: owl:ObjectProperty | E19: 0 | F19: 1 | G19: 1 | H19: 1 | I19: 1 | J19: 1 | K19: =MIN(F19:J19) -> 1 | L19: =MAX(F19:J19) -> 1 | M19: =L19-K19 -> 0 | O19: Pairwise J_w — ABox only
A20: F16 | B20: d:nombre | C20: rdf:type | D20: owl:DatatypeProperty | E20: 0 | F20: 1 | G20: 1 | H20: 1 | I20: 1 | J20: 1 | K20: =MIN(F20:J20) -> 1 | L20: =MAX(F20:J20) -> 1 | M20: =L20-K20 -> 0 | P20: R1 | Q20: R2 | R20: R3 | S20: R4 | T20: R5
A21: F17 | B21: d:rango | C21: rdf:type | D21: owl:DatatypeProperty | E21: 0 | F21: 1 | G21: 1 | H21: 1 | I21: 1 | J21: 1 | K21: =MIN(F21:J21) -> 1 | L21: =MAX(F21:J21) -> 1 | M21: =L21-K21 -> 0 | O21: R1 | P21: =SUMPRODUCT($E$5:$E$32*(($F$5:$F$32<$F$5:$F$32)*$F$5:$F$32+($F$5:$F$32>=$F$5:$F$32)*$F$5:$F$32))/SUMPRODUCT($E$5:$E$32*(($F$5:$F$32>$F$5:$F$32)*$F$5:$F$32+($F$5:$F$32<=$F$5:$F$32)*$F$5:$F$32)) -> 1 | Q21: =SUMPRODUCT($E$5:$E$32*(($F$5:$F$32<$G$5:$G$32)*$F$5:$F$32+($F$5:$F$32>=$G$5:$G$32)*$G$5:$G$32))/SUMPRODUCT($E$5:$E$32*(($F$5:$F$32>$G$5:$G$32)*$F$5:$F$32+($F$5:$F$32<=$G$5:$G$32)*$G$5:$G$32)) -> 1 | R21: =SUMPRODUCT($E$5:$E$32*(($F$5:$F$32<$H$5:$H$32)*$F$5:$F$32+($F$5:$F$32>=$H$5:$H$32)*$H$5:$H$32))/SUMPRODUCT($E$5:$E$32*(($F$5:$F$32>$H$5:$H$32)*$F$5:$F$32+($F$5:$F$32<=$H$5:$H$32)*$H$5:$H$32)) -> 1 | S21: =SUMPRODUCT($E$5:$E$32*(($F$5:$F$32<$I$5:$I$32)*$F$5:$F$32+($F$5:$F$32>=$I$5:$I$32)*$I$5:$I$32))/SUMPRODUCT($E$5:$E$32*(($F$5:$F$32>$I$5:$I$32)*$F$5:$F$32+($F$5:$F$32<=$I$5:$I$32)*$I$5:$I$32)) -> 0.625 | T21: =SUMPRODUCT($E$5:$E$32*(($F$5:$F$32<$J$5:$J$32)*$F$5:$F$32+($F$5:$F$32>=$J$5:$J$32)*$J$5:$J$32))/SUMPRODUCT($E$5:$E$32*(($F$5:$F$32>$J$5:$J$32)*$F$5:$F$32+($F$5:$F$32<=$J$5:$J$32)*$J$5:$J$32)) -> 1
A22: F18 | B22: d:stolenBy | C22: rdf:type | D22: owl:ObjectProperty | E22: 0 | F22: 1 | G22: 1 | H22: 1 | I22: 1 | J22: 1 | K22: =MIN(F22:J22) -> 1 | L22: =MAX(F22:J22) -> 1 | M22: =L22-K22 -> 0 | O22: R2 | P22: =SUMPRODUCT($E$5:$E$32*(($G$5:$G$32<$F$5:$F$32)*$G$5:$G$32+($G$5:$G$32>=$F$5:$F$32)*$F$5:$F$32))/SUMPRODUCT($E$5:$E$32*(($G$5:$G$32>$F$5:$F$32)*$G$5:$G$32+($G$5:$G$32<=$F$5:$F$32)*$F$5:$F$32)) -> 1 | Q22: =SUMPRODUCT($E$5:$E$32*(($G$5:$G$32<$G$5:$G$32)*$G$5:$G$32+($G$5:$G$32>=$G$5:$G$32)*$G$5:$G$32))/SUMPRODUCT($E$5:$E$32*(($G$5:$G$32>$G$5:$G$32)*$G$5:$G$32+($G$5:$G$32<=$G$5:$G$32)*$G$5:$G$32)) -> 1 | R22: =SUMPRODUCT($E$5:$E$32*(($G$5:$G$32<$H$5:$H$32)*$G$5:$G$32+($G$5:$G$32>=$H$5:$H$32)*$H$5:$H$32))/SUMPRODUCT($E$5:$E$32*(($G$5:$G$32>$H$5:$H$32)*$G$5:$G$32+($G$5:$G$32<=$H$5:$H$32)*$H$5:$H$32)) -> 1 | S22: =SUMPRODUCT($E$5:$E$32*(($G$5:$G$32<$I$5:$I$32)*$G$5:$G$32+($G$5:$G$32>=$I$5:$I$32)*$I$5:$I$32))/SUMPRODUCT($E$5:$E$32*(($G$5:$G$32>$I$5:$I$32)*$G$5:$G$32+($G$5:$G$32<=$I$5:$I$32)*$I$5:$I$32)) -> 0.625 | T22: =SUMPRODUCT($E$5:$E$32*(($G$5:$G$32<$J$5:$J$32)*$G$5:$G$32+($G$5:$G$32>=$J$5:$J$32)*$J$5:$J$32))/SUMPRODUCT($E$5:$E$32*(($G$5:$G$32>$J$5:$J$32)*$G$5:$G$32+($G$5:$G$32<=$J$5:$J$32)*$J$5:$J$32)) -> 1
A23: F19 | B23: d:stolenthing | C23: rdf:type | D23: owl:ObjectProperty | E23: 0 | F23: 1 | G23: 1 | H23: 1 | I23: 1 | J23: 1 | K23: =MIN(F23:J23) -> 1 | L23: =MAX(F23:J23) -> 1 | M23: =L23-K23 -> 0 | O23: R3 | P23: =SUMPRODUCT($E$5:$E$32*(($H$5:$H$32<$F$5:$F$32)*$H$5:$H$32+($H$5:$H$32>=$F$5:$F$32)*$F$5:$F$32))/SUMPRODUCT($E$5:$E$32*(($H$5:$H$32>$F$5:$F$32)*$H$5:$H$32+($H$5:$H$32<=$F$5:$F$32)*$F$5:$F$32)) -> 1 | Q23: =SUMPRODUCT($E$5:$E$32*(($H$5:$H$32<$G$5:$G$32)*$H$5:$H$32+($H$5:$H$32>=$G$5:$G$32)*$G$5:$G$32))/SUMPRODUCT($E$5:$E$32*(($H$5:$H$32>$G$5:$G$32)*$H$5:$H$32+($H$5:$H$32<=$G$5:$G$32)*$G$5:$G$32)) -> 1 | R23: =SUMPRODUCT($E$5:$E$32*(($H$5:$H$32<$H$5:$H$32)*$H$5:$H$32+($H$5:$H$32>=$H$5:$H$32)*$H$5:$H$32))/SUMPRODUCT($E$5:$E$32*(($H$5:$H$32>$H$5:$H$32)*$H$5:$H$32+($H$5:$H$32<=$H$5:$H$32)*$H$5:$H$32)) -> 1 | S23: =SUMPRODUCT($E$5:$E$32*(($H$5:$H$32<$I$5:$I$32)*$H$5:$H$32+($H$5:$H$32>=$I$5:$I$32)*$I$5:$I$32))/SUMPRODUCT($E$5:$E$32*(($H$5:$H$32>$I$5:$I$32)*$H$5:$H$32+($H$5:$H$32<=$I$5:$I$32)*$I$5:$I$32)) -> 0.625 | T23: =SUMPRODUCT($E$5:$E$32*(($H$5:$H$32<$J$5:$J$32)*$H$5:$H$32+($H$5:$H$32>=$J$5:$J$32)*$J$5:$J$32))/SUMPRODUCT($E$5:$E$32*(($H$5:$H$32>$J$5:$J$32)*$H$5:$H$32+($H$5:$H$32<=$J$5:$J$32)*$J$5:$J$32)) -> 1
A24: F20 | B24: d:usedByOwner | C24: rdf:type | D24: owl:ObjectProperty | E24: 0 | F24: 1 | G24: 1 | H24: 1 | I24: 1 | J24: 1 | K24: =MIN(F24:J24) -> 1 | L24: =MAX(F24:J24) -> 1 | M24: =L24-K24 -> 0 | O24: R4 | P24: =SUMPRODUCT($E$5:$E$32*(($I$5:$I$32<$F$5:$F$32)*$I$5:$I$32+($I$5:$I$32>=$F$5:$F$32)*$F$5:$F$32))/SUMPRODUCT($E$5:$E$32*(($I$5:$I$32>$F$5:$F$32)*$I$5:$I$32+($I$5:$I$32<=$F$5:$F$32)*$F$5:$F$32)) -> 0.625 | Q24: =SUMPRODUCT($E$5:$E$32*(($I$5:$I$32<$G$5:$G$32)*$I$5:$I$32+($I$5:$I$32>=$G$5:$G$32)*$G$5:$G$32))/SUMPRODUCT($E$5:$E$32*(($I$5:$I$32>$G$5:$G$32)*$I$5:$I$32+($I$5:$I$32<=$G$5:$G$32)*$G$5:$G$32)) -> 0.625 | R24: =SUMPRODUCT($E$5:$E$32*(($I$5:$I$32<$H$5:$H$32)*$I$5:$I$32+($I$5:$I$32>=$H$5:$H$32)*$H$5:$H$32))/SUMPRODUCT($E$5:$E$32*(($I$5:$I$32>$H$5:$H$32)*$I$5:$I$32+($I$5:$I$32<=$H$5:$H$32)*$H$5:$H$32)) -> 0.625 | S24: =SUMPRODUCT($E$5:$E$32*(($I$5:$I$32<$I$5:$I$32)*$I$5:$I$32+($I$5:$I$32>=$I$5:$I$32)*$I$5:$I$32))/SUMPRODUCT($E$5:$E$32*(($I$5:$I$32>$I$5:$I$32)*$I$5:$I$32+($I$5:$I$32<=$I$5:$I$32)*$I$5:$I$32)) -> 1 | T24: =SUMPRODUCT($E$5:$E$32*(($I$5:$I$32<$J$5:$J$32)*$I$5:$I$32+($I$5:$I$32>=$J$5:$J$32)*$J$5:$J$32))/SUMPRODUCT($E$5:$E$32*(($I$5:$I$32>$J$5:$J$32)*$I$5:$I$32+($I$5:$I$32<=$J$5:$J$32)*$J$5:$J$32)) -> 0.625
A25: F21 | B25: d:valor | C25: rdf:type | D25: owl:DatatypeProperty | E25: 0 | F25: 1 | G25: 1 | H25: 1 | I25: 1 | J25: 1 | K25: =MIN(F25:J25) -> 1 | L25: =MAX(F25:J25) -> 1 | M25: =L25-K25 -> 0 | O25: R5 | P25: =SUMPRODUCT($E$5:$E$32*(($J$5:$J$32<$F$5:$F$32)*$J$5:$J$32+($J$5:$J$32>=$F$5:$F$32)*$F$5:$F$32))/SUMPRODUCT($E$5:$E$32*(($J$5:$J$32>$F$5:$F$32)*$J$5:$J$32+($J$5:$J$32<=$F$5:$F$32)*$F$5:$F$32)) -> 1 | Q25: =SUMPRODUCT($E$5:$E$32*(($J$5:$J$32<$G$5:$G$32)*$J$5:$J$32+($J$5:$J$32>=$G$5:$G$32)*$G$5:$G$32))/SUMPRODUCT($E$5:$E$32*(($J$5:$J$32>$G$5:$G$32)*$J$5:$J$32+($J$5:$J$32<=$G$5:$G$32)*$G$5:$G$32)) -> 1 | R25: =SUMPRODUCT($E$5:$E$32*(($J$5:$J$32<$H$5:$H$32)*$J$5:$J$32+($J$5:$J$32>=$H$5:$H$32)*$H$5:$H$32))/SUMPRODUCT($E$5:$E$32*(($J$5:$J$32>$H$5:$H$32)*$J$5:$J$32+($J$5:$J$32<=$H$5:$H$32)*$H$5:$H$32)) -> 1 | S25: =SUMPRODUCT($E$5:$E$32*(($J$5:$J$32<$I$5:$I$32)*$J$5:$J$32+($J$5:$J$32>=$I$5:$I$32)*$I$5:$I$32))/SUMPRODUCT($E$5:$E$32*(($J$5:$J$32>$I$5:$I$32)*$J$5:$J$32+($J$5:$J$32<=$I$5:$I$32)*$I$5:$I$32)) -> 0.625 | T25: =SUMPRODUCT($E$5:$E$32*(($J$5:$J$32<$J$5:$J$32)*$J$5:$J$32+($J$5:$J$32>=$J$5:$J$32)*$J$5:$J$32))/SUMPRODUCT($E$5:$E$32*(($J$5:$J$32>$J$5:$J$32)*$J$5:$J$32+($J$5:$J$32<=$J$5:$J$32)*$J$5:$J$32)) -> 1
A26: F22 | B26: d:belongsTo | C26: rdfs:label | D26: Lit | E26: 0 | F26: 1 | G26: 1 | H26: 1 | I26: 1 | J26: 1 | K26: =MIN(F26:J26) -> 1 | L26: =MAX(F26:J26) -> 1 | M26: =L26-K26 -> 0
A27: F23 | B27: d:nombre | C27: rdfs:label | D27: Lit | E27: 0 | F27: 1 | G27: 1 | H27: 1 | I27: 1 | J27: 1 | K27: =MIN(F27:J27) -> 1 | L27: =MAX(F27:J27) -> 1 | M27: =L27-K27 -> 0 | O27: Pair | P27: J_w full graph | Q27: J_w ABox
A28: F24 | B28: d:rango | C28: rdfs:label | D28: Lit | E28: 0 | F28: 1 | G28: 1 | H28: 1 | I28: 1 | J28: 1 | K28: =MIN(F28:J28) -> 1 | L28: =MAX(F28:J28) -> 1 | M28: =L28-K28 -> 0 | O28: R1–R2 | P28: =Q13 -> 1 | Q28: =Q21 -> 1
A29: F25 | B29: d:stolenBy | C29: rdfs:label | D29: Lit | E29: 0 | F29: 1 | G29: 1 | H29: 1 | I29: 1 | J29: 1 | K29: =MIN(F29:J29) -> 1 | L29: =MAX(F29:J29) -> 1 | M29: =L29-K29 -> 0 | O29: R1–R3 | P29: =R13 -> 1 | Q29: =R21 -> 1
A30: F26 | B30: d:stolenthing | C30: rdfs:label | D30: Lit | E30: 0 | F30: 1 | G30: 1 | H30: 1 | I30: 1 | J30: 1 | K30: =MIN(F30:J30) -> 1 | L30: =MAX(F30:J30) -> 1 | M30: =L30-K30 -> 0 | O30: R1–R4 | P30: =S13 -> 0.82352941 | Q30: =S21 -> 0.625
A31: F27 | B31: d:usedByOwner | C31: rdfs:label | D31: Lit | E31: 0 | F31: 1 | G31: 1 | H31: 1 | I31: 1 | J31: 1 | K31: =MIN(F31:J31) -> 1 | L31: =MAX(F31:J31) -> 1 | M31: =L31-K31 -> 0 | O31: R1–R5 | P31: =T13 -> 1 | Q31: =T21 -> 1
A32: F28 | B32: d:valor | C32: rdfs:label | D32: Lit | E32: 0 | F32: 1 | G32: 1 | H32: 1 | I32: 1 | J32: 1 | K32: =MIN(F32:J32) -> 1 | L32: =MAX(F32:J32) -> 1 | M32: =L32-K32 -> 0 | O32: R2–R3 | P32: =R14 -> 1 | Q32: =R22 -> 1
D33: Triples (full graph) | F33: =SUM(F5:F32) -> 34 | G33: =SUM(G5:G32) -> 34 | H33: =SUM(H5:H32) -> 34 | I33: =SUM(I5:I32) -> 28 | J33: =SUM(J5:J32) -> 34 | K33: =SUM(K5:K32) -> 28 | L33: =SUM(L5:L32) -> 34 | O33: R2–R4 | P33: =S14 -> 0.82352941 | Q33: =S22 -> 0.625
D34: Triples (ABox) | F34: =SUMPRODUCT($E$5:$E$32,F5:F32) -> 16 | G34: =SUMPRODUCT($E$5:$E$32,G5:G32) -> 16 | H34: =SUMPRODUCT($E$5:$E$32,H5:H32) -> 16 | I34: =SUMPRODUCT($E$5:$E$32,I5:I32) -> 10 | J34: =SUMPRODUCT($E$5:$E$32,J5:J32) -> 16 | K34: =SUMPRODUCT($E$5:$E$32,K5:K32) -> 10 | L34: =SUMPRODUCT($E$5:$E$32,L5:L32) -> 16 | O34: R2–R5 | P34: =T14 -> 1 | Q34: =T22 -> 1
D35: Distinct shapes (full graph) | F35: =COUNTIF(F5:F32,">0") -> 28 | G35: =COUNTIF(G5:G32,">0") -> 28 | H35: =COUNTIF(H5:H32,">0") -> 28 | I35: =COUNTIF(I5:I32,">0") -> 28 | J35: =COUNTIF(J5:J32,">0") -> 28 | O35: R3–R4 | P35: =S15 -> 0.82352941 | Q35: =S23 -> 0.625
D36: Distinct shapes (ABox) | F36: =COUNTIFS(F5:F32,">0",$E$5:$E$32,1) -> 10 | G36: =COUNTIFS(G5:G32,">0",$E$5:$E$32,1) -> 10 | H36: =COUNTIFS(H5:H32,">0",$E$5:$E$32,1) -> 10 | I36: =COUNTIFS(I5:I32,">0",$E$5:$E$32,1) -> 10 | J36: =COUNTIFS(J5:J32,">0",$E$5:$E$32,1) -> 10 | O36: R3–R5 | P36: =T15 -> 1 | Q36: =T23 -> 1
O37: R4–R5 | P37: =T16 -> 0.82352941 | Q37: =T24 -> 0.625
O39: Statistic | P39: Full graph | Q39: ABox
O40: Mean of the 10 pairs | P40: =AVERAGE(P28:P37) -> 0.92941176 | Q40: =AVERAGE(Q28:Q37) -> 0.85
O41: SD of the 10 pairs (sample) | P41: =STDEV(P28:P37) -> 0.09112902 | Q41: =STDEV(Q28:Q37) -> 0.19364917
O42: Minimum pair | P42: =MIN(P28:P37) -> 0.82352941 | Q42: =MIN(Q28:Q37) -> 0.625
...

Sheet Report_3
A1: Report 3 — shape counts per run and pairwise multiset Jaccard
A2: Blue cells = shape counts extracted from the RDF files (inputs). Black cells = formulas. Shaded rows = shapes whose count differs across runs.
A4: Shape ID | B4: Subject shape | C4: Predicate | D4: Object shape | E4: ABox (1) / TBox (0) | F4: R1 | G4: R2 | H4: R3 | I4: R4 | J4: R5 | K4: Min (5 runs) | L4: Max (5 runs) | M4: Max − Min | O4: Run | P4: Source RDF file
A5: F01 | B5: <d:Accused+d:CollaborationWithCriminalOrganisation+d:MinorAccomplice+d:OlderDetention> | C5: rdf:type | D5: d:Accused | E5: 1 | F5: 1 | G5: 1 | H5: 1 | I5: 1 | J5: 1 | K5: =MIN(F5:J5) -> 1 | L5: =MAX(F5:J5) -> 1 | M5: =L5-K5 -> 0 | O5: R1 | P5: 1INFORME_Atestado3.rdf
A6: F02 | B6: <d:Accused+d:CollaborationWithCriminalOrganisation+d:MinorAccomplice+d:OlderDetention> | C6: rdf:type | D6: d:CollaborationWithCriminalOrganisation | E6: 1 | F6: 1 | G6: 1 | H6: 1 | I6: 1 | J6: 1 | K6: =MIN(F6:J6) -> 1 | L6: =MAX(F6:J6) -> 1 | M6: =L6-K6 -> 0 | O6: R2 | P6: 1INFORME_Atestado3 (1).rdf
A7: F03 | B7: <d:Accused+d:CollaborationWithCriminalOrganisation+d:MinorAccomplice+d:OlderDetention> | C7: rdf:type | D7: d:MinorAccomplice | E7: 1 | F7: 1 | G7: 1 | H7: 1 | I7: 1 | J7: 1 | K7: =MIN(F7:J7) -> 1 | L7: =MAX(F7:J7) -> 1 | M7: =L7-K7 -> 0 | O7: R3 | P7: 1INFORME_Atestado3 (2).rdf
A8: F04 | B8: <d:Accused+d:CollaborationWithCriminalOrganisation+d:MinorAccomplice+d:OlderDetention> | C8: rdf:type | D8: d:OlderDetention | E8: 1 | F8: 1 | G8: 1 | H8: 1 | I8: 1 | J8: 1 | K8: =MIN(F8:J8) -> 1 | L8: =MAX(F8:J8) -> 1 | M8: =L8-K8 -> 0 | O8: R4 | P8: 1INFORME_Atestado3 (3).rdf
A9: F05 | B9: <d:BurglaryCrime> | C9: rdf:type | D9: d:BurglaryCrime | E9: 1 | F9: 1 | G9: 1 | H9: 1 | I9: 1 | J9: 1 | K9: =MIN(F9:J9) -> 1 | L9: =MAX(F9:J9) -> 1 | M9: =L9-K9 -> 0 | O9: R5 | P9: 1INFORME_Atestado3 (4).rdf
A10: F06 | B10: <d:HouseOrPremiseBreaking> | C10: rdf:type | D10: d:HouseOrPremiseBreaking | E10: 1 | F10: 1 | G10: 1 | H10: 1 | I10: 1 | J10: 1 | K10: =MIN(F10:J10) -> 1 | L10: =MAX(F10:J10) -> 1 | M10: =L10-K10 -> 0
A11: F07 | B11: <d:Punishment> | C11: rdf:type | D11: d:Punishment | E11: 1 | F11: 1 | G11: 1 | H11: 1 | I11: 1 | J11: 1 | K11: =MIN(F11:J11) -> 1 | L11: =MAX(F11:J11) -> 1 | M11: =L11-K11 -> 0 | O11: Pairwise J_w — full graph
A12: F08 | B12: <d:Report> | C12: rdf:type | D12: d:Report | E12: 1 | F12: 1 | G12: 1 | H12: 1 | I12: 1 | J12: 1 | K12: =MIN(F12:J12) -> 1 | L12: =MAX(F12:J12) -> 1 | M12: =L12-K12 -> 0 | P12: R1 | Q12: R2 | R12: R3 | S12: R4 | T12: R5
A13: F09 | B13: <d:RobberyCharacteristic> | C13: rdf:type | D13: d:RobberyCharacteristic | E13: 1 | F13: 1 | G13: 1 | H13: 1 | I13: 1 | J13: 1 | K13: =MIN(F13:J13) -> 1 | L13: =MAX(F13:J13) -> 1 | M13: =L13-K13 -> 0 | O13: R1 | P13: =SUMPRODUCT((($F$5:$F$50<$F$5:$F$50)*$F$5:$F$50+($F$5:$F$50>=$F$5:$F$50)*$F$5:$F$50))/SUMPRODUCT((($F$5:$F$50>$F$5:$F$50)*$F$5:$F$50+($F$5:$F$50<=$F$5:$F$50)*$F$5:$F$50)) -> 1 | Q13: =SUMPRODUCT((($F$5:$F$50<$G$5:$G$50)*$F$5:$F$50+($F$5:$F$50>=$G$5:$G$50)*$G$5:$G$50))/SUMPRODUCT((($F$5:$F$50>$G$5:$G$50)*$F$5:$F$50+($F$5:$F$50<=$G$5:$G$50)*$G$5:$G$50)) -> 1 | R13: =SUMPRODUCT((($F$5:$F$50<$H$5:$H$50)*$F$5:$F$50+($F$5:$F$50>=$H$5:$H$50)*$H$5:$H$50))/SUMPRODUCT((($F$5:$F$50>$H$5:$H$50)*$F$5:$F$50+($F$5:$F$50<=$H$5:$H$50)*$H$5:$H$50)) -> 1 | S13: =SUMPRODUCT((($F$5:$F$50<$I$5:$I$50)*$F$5:$F$50+($F$5:$F$50>=$I$5:$I$50)*$I$5:$I$50))/SUMPRODUCT((($F$5:$F$50>$I$5:$I$50)*$F$5:$F$50+($F$5:$F$50<=$I$5:$I$50)*$I$5:$I$50)) -> 1 | T13: =SUMPRODUCT((($F$5:$F$50<$J$5:$J$50)*$F$5:$F$50+($F$5:$F$50>=$J$5:$J$50)*$J$5:$J$50))/SUMPRODUCT((($F$5:$F$50>$J$5:$J$50)*$F$5:$F$50+($F$5:$F$50<=$J$5:$J$50)*$J$5:$J$50)) -> 1
A14: F10 | B14: <d:StolenGoods> | C14: rdf:type | D14: d:StolenGoods | E14: 1 | F14: 2 | G14: 2 | H14: 2 | I14: 2 | J14: 2 | K14: =MIN(F14:J14) -> 2 | L14: =MAX(F14:J14) -> 2 | M14: =L14-K14 -> 0 | O14: R2 | P14: =SUMPRODUCT((($G$5:$G$50<$F$5:$F$50)*$G$5:$G$50+($G$5:$G$50>=$F$5:$F$50)*$F$5:$F$50))/SUMPRODUCT((($G$5:$G$50>$F$5:$F$50)*$G$5:$G$50+($G$5:$G$50<=$F$5:$F$50)*$F$5:$F$50)) -> 1 | Q14: =SUMPRODUCT((($G$5:$G$50<$G$5:$G$50)*$G$5:$G$50+($G$5:$G$50>=$G$5:$G$50)*$G$5:$G$50))/SUMPRODUCT((($G$5:$G$50>$G$5:$G$50)*$G$5:$G$50+($G$5:$G$50<=$G$5:$G$50)*$G$5:$G$50)) -> 1 | R14: =SUMPRODUCT((($G$5:$G$50<$H$5:$H$50)*$G$5:$G$50+($G$5:$G$50>=$H$5:$H$50)*$H$5:$H$50))/SUMPRODUCT((($G$5:$G$50>$H$5:$H$50)*$G$5:$G$50+($G$5:$G$50<=$H$5:$H$50)*$H$5:$H$50)) -> 1 | S14: =SUMPRODUCT((($G$5:$G$50<$I$5:$I$50)*$G$5:$G$50+($G$5:$G$50>=$I$5:$I$50)*$I$5:$I$50))/SUMPRODUCT((($G$5:$G$50>$I$5:$I$50)*$G$5:$G$50+($G$5:$G$50<=$I$5:$I$50)*$I$5:$I$50)) -> 1 | T14: =SUMPRODUCT((($G$5:$G$50<$J$5:$J$50)*$G$5:$G$50+($G$5:$G$50>=$J$5:$J$50)*$J$5:$J$50))/SUMPRODUCT((($G$5:$G$50>$J$5:$J$50)*$G$5:$G$50+($G$5:$G$50<=$J$5:$J$50)*$J$5:$J$50)) -> 1
A15: F11 | B15: <d:Victim> | C15: rdf:type | D15: d:Victim | E15: 1 | F15: 1 | G15: 1 | H15: 1 | I15: 1 | J15: 1 | K15: =MIN(F15:J15) -> 1 | L15: =MAX(F15:J15) -> 1 | M15: =L15-K15 -> 0 | O15: R3 | P15: =SUMPRODUCT((($H$5:$H$50<$F$5:$F$50)*$H$5:$H$50+($H$5:$H$50>=$F$5:$F$50)*$F$5:$F$50))/SUMPRODUCT((($H$5:$H$50>$F$5:$F$50)*$H$5:$H$50+($H$5:$H$50<=$F$5:$F$50)*$F$5:$F$50)) -> 1 | Q15: =SUMPRODUCT((($H$5:$H$50<$G$5:$G$50)*$H$5:$H$50+($H$5:$H$50>=$G$5:$G$50)*$G$5:$G$50))/SUMPRODUCT((($H$5:$H$50>$G$5:$G$50)*$H$5:$H$50+($H$5:$H$50<=$G$5:$G$50)*$G$5:$G$50)) -> 1 | R15: =SUMPRODUCT((($H$5:$H$50<$H$5:$H$50)*$H$5:$H$50+($H$5:$H$50>=$H$5:$H$50)*$H$5:$H$50))/SUMPRODUCT((($H$5:$H$50>$H$5:$H$50)*$H$5:$H$50+($H$5:$H$50<=$H$5:$H$50)*$H$5:$H$50)) -> 1 | S15: =SUMPRODUCT((($H$5:$H$50<$I$5:$I$50)*$H$5:$H$50+($H$5:$H$50>=$I$5:$I$50)*$I$5:$I$50))/SUMPRODUCT((($H$5:$H$50>$I$5:$I$50)*$H$5:$H$50+($H$5:$H$50<=$I$5:$I$50)*$I$5:$I$50)) -> 1 | T15: =SUMPRODUCT((($H$5:$H$50<$J$5:$J$50)*$H$5:$H$50+($H$5:$H$50>=$J$5:$J$50)*$J$5:$J$50))/SUMPRODUCT((($H$5:$H$50>$J$5:$J$50)*$H$5:$H$50+($H$5:$H$50<=$J$5:$J$50)*$J$5:$J$50)) -> 1
A16: F12 | B16: <d:Accused+d:CollaborationWithCriminalOrganisation+d:MinorAccomplice+d:OlderDetention> | C16: d:hasPreviusSentence | D16: <d:Punishment> | E16: 1 | F16: 1 | G16: 1 | H16: 1 | I16: 1 | J16: 1 | K16: =MIN(F16:J16) -> 1 | L16: =MAX(F16:J16) -> 1 | M16: =L16-K16 -> 0 | O16: R4 | P16: =SUMPRODUCT((($I$5:$I$50<$F$5:$F$50)*$I$5:$I$50+($I$5:$I$50>=$F$5:$F$50)*$F$5:$F$50))/SUMPRODUCT((($I$5:$I$50>$F$5:$F$50)*$I$5:$I$50+($I$5:$I$50<=$F$5:$F$50)*$F$5:$F$50)) -> 1 | Q16: =SUMPRODUCT((($I$5:$I$50<$G$5:$G$50)*$I$5:$I$50+($I$5:$I$50>=$G$5:$G$50)*$G$5:$G$50))/SUMPRODUCT((($I$5:$I$50>$G$5:$G$50)*$I$5:$I$50+($I$5:$I$50<=$G$5:$G$50)*$G$5:$G$50)) -> 1 | R16: =SUMPRODUCT((($I$5:$I$50<$H$5:$H$50)*$I$5:$I$50+($I$5:$I$50>=$H$5:$H$50)*$H$5:$H$50))/SUMPRODUCT((($I$5:$I$50>$H$5:$H$50)*$I$5:$I$50+($I$5:$I$50<=$H$5:$H$50)*$H$5:$H$50)) -> 1 | S16: =SUMPRODUCT((($I$5:$I$50<$I$5:$I$50)*$I$5:$I$50+($I$5:$I$50>=$I$5:$I$50)*$I$5:$I$50))/SUMPRODUCT((($I$5:$I$50>$I$5:$I$50)*$I$5:$I$50+($I$5:$I$50<=$I$5:$I$50)*$I$5:$I$50)) -> 1 | T16: =SUMPRODUCT((($I$5:$I$50<$J$5:$J$50)*$I$5:$I$50+($I$5:$I$50>=$J$5:$J$50)*$J$5:$J$50))/SUMPRODUCT((($I$5:$I$50>$J$5:$J$50)*$I$5:$I$50+($I$5:$I$50<=$J$5:$J$50)*$J$5:$J$50)) -> 1
A17: F13 | B17: <d:Punishment> | C17: d:num | D17: Lit^^xsd:integer | E17: 1 | F17: 1 | G17: 1 | H17: 1 | I17: 1 | J17: 1 | K17: =MIN(F17:J17) -> 1 | L17: =MAX(F17:J17) -> 1 | M17: =L17-K17 -> 0 | O17: R5 | P17: =SUMPRODUCT((($J$5:$J$50<$F$5:$F$50)*$J$5:$J$50+($J$5:$J$50>=$F$5:$F$50)*$F$5:$F$50))/SUMPRODUCT((($J$5:$J$50>$F$5:$F$50)*$J$5:$J$50+($J$5:$J$50<=$F$5:$F$50)*$F$5:$F$50)) -> 1 | Q17: =SUMPRODUCT((($J$5:$J$50<$G$5:$G$50)*$J$5:$J$50+($J$5:$J$50>=$G$5:$G$50)*$G$5:$G$50))/SUMPRODUCT((($J$5:$J$50>$G$5:$G$50)*$J$5:$J$50+($J$5:$J$50<=$G$5:$G$50)*$G$5:$G$50)) -> 1 | R17: =SUMPRODUCT((($J$5:$J$50<$H$5:$H$50)*$J$5:$J$50+($J$5:$J$50>=$H$5:$H$50)*$H$5:$H$50))/SUMPRODUCT((($J$5:$J$50>$H$5:$H$50)*$J$5:$J$50+($J$5:$J$50<=$H$5:$H$50)*$H$5:$H$50)) -> 1 | S17: =SUMPRODUCT((($J$5:$J$50<$I$5:$I$50)*$J$5:$J$50+($J$5:$J$50>=$I$5:$I$50)*$I$5:$I$50))/SUMPRODUCT((($J$5:$J$50>$I$5:$I$50)*$J$5:$J$50+($J$5:$J$50<=$I$5:$I$50)*$I$5:$I$50)) -> 1 | T17: =SUMPRODUCT((($J$5:$J$50<$J$5:$J$50)*$J$5:$J$50+($J$5:$J$50>=$J$5:$J$50)*$J$5:$J$50))/SUMPRODUCT((($J$5:$J$50>$J$5:$J$50)*$J$5:$J$50+($J$5:$J$50<=$J$5:$J$50)*$J$5:$J$50)) -> 1
A18: F14 | B18: <d:Report> | C18: d:hasOffenceCharacteristic | D18: <d:BurglaryCrime> | E18: 1 | F18: 1 | G18: 1 | H18: 1 | I18: 1 | J18: 1 | K18: =MIN(F18:J18) -> 1 | L18: =MAX(F18:J18) -> 1 | M18: =L18-K18 -> 0
A19: F15 | B19: <d:Report> | C19: d:hasOffenceCharacteristic | D19: <d:HouseOrPremiseBreaking> | E19: 1 | F19: 1 | G19: 1 | H19: 1 | I19: 1 | J19: 1 | K19: =MIN(F19:J19) -> 1 | L19: =MAX(F19:J19) -> 1 | M19: =L19-K19 -> 0 | O19: Pairwise J_w — ABox only
A20: F16 | B20: <d:Report> | C20: d:hasOffenceCharacteristic | D20: <d:RobberyCharacteristic> | E20: 1 | F20: 1 | G20: 1 | H20: 1 | I20: 1 | J20: 1 | K20: =MIN(F20:J20) -> 1 | L20: =MAX(F20:J20) -> 1 | M20: =L20-K20 -> 0 | P20: R1 | Q20: R2 | R20: R3 | S20: R4 | T20: R5
